<?xml version="1.0" encoding="utf-8"?>
<!-- =================================================================================== -->
<!-- |    This document was autogenerated by xacro from test_agv_arm.xacro             | -->
<!-- |    EDITING THIS FILE BY HAND IS NOT RECOMMENDED                                 | -->
<!-- =================================================================================== -->
<robot name="agv_arm">
  <!-- T265 Fisheye:

  gazebo_ros_camera supports only plumb_bob
  D: [-0.007419134024530649, 0.041209351271390915, -0.03811917081475258, 0.006366158835589886, 0.0]

  <distortionK1>-0.007419134024530649</distortionK1>
  <distortionK2>0.041209351271390915</distortionK2>
  <distortionK3>-0.03811917081475258</distortionK3>
  <distortionT1>0.006366158835589886</distortionT1>
  <distortionT2>0.0</distortionT2>

       [fx'  0  cx' Tx]
   P = [ 0  fy' cy' Ty]
       [ 0   0   1   0]

   P : [ 285.5480041503906, 0.0, 416.00531005859375, 0.0,
         0.0, 285.3793029785156, 403.38909912109375, 0.0,
         0.0, 0.0, 1.0, 0.0 ]

  <CxPrime>416.00531005859375</CxPrime>

       [fx  0 cx]
   K = [ 0 fy cy]
       [ 0  0  1]

   K : [ 285.5480041503906, 0.0, 416.00531005859375,
         0.0, 285.3793029785156, 403.38909912109375,
         0.0, 0.0, 1.0]

  <Cx>16.00531005859375</Cx>
  <Cy>403.38909912109375</Cy>

  -->
  <!-- INTEL REALSENSE T265 -->
  <!-- INTEL REALSENSE D435 -->
  <!-- INTEL REALSENSE R200 -->
  <link name="base_link">
    <inertial>
      <origin rpy="0 0 0" xyz="0.570341970178263 -1.88528825872453 -0.303668536274056"/>
      <mass value="5.35773705728221"/>
      <inertia ixx="0.0789888195141756" ixy="0.0296735251325005" ixz="6.86804058743938E-05" iyy="0.0636306474316624" iyz="-6.67380007365019E-05" izz="0.111507797834734"/>
    </inertial>
    <visual>
      <origin rpy="0 0 0" xyz="0 0 0"/>
      <geometry>
        <mesh filename="package://agv_arm/meshes/base_link.STL"/>
      </geometry>
      <material name="">
        <color rgba="1 1 1 1"/>
      </material>
    </visual>
    <collision>
      <origin rpy="0 0 0" xyz="0 0 0"/>
      <geometry>
        <mesh filename="package://agv_arm/meshes/base_link.STL"/>
      </geometry>
    </collision>
  </link>
  <link name="left_link">
    <inertial>
      <origin rpy="0 0 0" xyz="-3.3515E-11 -2.999E-08 -0.0034865"/>
      <mass value="1.043"/>
      <inertia ixx="0.0031452" ixy="-1.693E-13" ixz="1.1637E-08" iyy="0.0031454" iyz="7.3781E-11" izz="0.005867"/>
    </inertial>
    <visual>
      <origin rpy="0 0 0" xyz="0 0 0"/>
      <geometry>
        <mesh filename="package://agv_arm/meshes/left_link.STL"/>
      </geometry>
      <material name="">
        <color rgba="1 1 1 1"/>
      </material>
    </visual>
    <collision>
      <origin rpy="0 0 0" xyz="0 0 0"/>
      <geometry>
        <mesh filename="package://agv_arm/meshes/left_link.STL"/>
      </geometry>
    </collision>
  </link>
  <joint name="left_joint" type="revolute">
    <origin rpy="1.5708 -0.087266 -0.7854" xyz="0.45399 -2.0016 -0.34097"/>
    <parent link="base_link"/>
    <child link="left_link"/>
    <axis xyz="0 0 -1"/>
    <limit effort="1" lower="-1111" upper="1111" velocity="1"/>
  </joint>
  <link name="right_link">
    <inertial>
      <origin rpy="0 0 0" xyz="-3.3515E-11 -2.999E-08 -0.0034865"/>
      <mass value="1.043"/>
      <inertia ixx="0.0031452" ixy="-1.693E-13" ixz="1.1637E-08" iyy="0.0031454" iyz="7.3781E-11" izz="0.005867"/>
    </inertial>
    <visual>
      <origin rpy="0 0 0" xyz="0 0 0"/>
      <geometry>
        <mesh filename="package://agv_arm/meshes/right_link.STL"/>
      </geometry>
      <material name="">
        <color rgba="1 1 1 1"/>
      </material>
    </visual>
    <collision>
      <origin rpy="0 0 0" xyz="0 0 0"/>
      <geometry>
        <mesh filename="package://agv_arm/meshes/right_link.STL"/>
      </geometry>
    </collision>
  </link>
  <joint name="right_joint" type="revolute">
    <origin rpy="1.5708 -0.087266 2.3562" xyz="0.68663 -1.7689 -0.34097"/>
    <parent link="base_link"/>
    <child link="right_link"/>
    <axis xyz="0 0 -1"/>
    <limit effort="1" lower="-1111" upper="1111" velocity="1"/>
  </joint>
  <link name="lidar_link">
    <inertial>
      <origin rpy="0 0 0" xyz="-0.00029615 1.1284E-09 -0.020472"/>
      <mass value="0.13159"/>
      <inertia ixx="7.1462E-05" ixy="3.3196E-12" ixz="8.6535E-07" iyy="7.2311E-05" iyz="-2.4711E-12" izz="4.4677E-05"/>
    </inertial>
    <visual>
      <origin rpy="0 0 0" xyz="0 0 0"/>
      <geometry>
        <mesh filename="package://agv_arm/meshes/lidar_link.STL"/>
      </geometry>
      <material name="">
        <color rgba="1 1 1 1"/>
      </material>
    </visual>
    <collision>
      <origin rpy="0 0 0" xyz="0 0 0"/>
      <geometry>
        <mesh filename="package://agv_arm/meshes/lidar_link.STL"/>
      </geometry>
    </collision>
  </link>
  <joint name="lidar_joint" type="fixed">
    <origin rpy="0 0 2.35619449021312" xyz="0.392951119656292 -1.70790005142473 -0.152629369887627"/>
    <parent link="base_link"/>
    <child link="lidar_link"/>
    <axis xyz="0 0 0"/>
  </joint>
  <link name="pwr_link">
    <inertial>
      <origin rpy="0 0 0" xyz="0.0149998988087228 0.0149999922703186 0.0302002587155129"/>
      <mass value="0.0494935351719684"/>
      <inertia ixx="2.25637713562706E-05" ixy="1.12310101294322E-11" ixz="1.59879773971087E-10" iyy="2.25636840533923E-05" iyz="1.00765741356031E-11" izz="6.57719217809586E-06"/>
    </inertial>
    <visual>
      <origin rpy="0 0 0" xyz="0 0 0"/>
      <geometry>
        <mesh filename="package://agv_arm/meshes/pwr_link.STL"/>
      </geometry>
      <material name="">
        <color rgba="1 1 1 1"/>
      </material>
    </visual>
    <collision>
      <origin rpy="0 0 0" xyz="0 0 0"/>
      <geometry>
        <mesh filename="package://agv_arm/meshes/pwr_link.STL"/>
      </geometry>
    </collision>
  </link>
  <joint name="pwr_joint" type="fixed">
    <origin rpy="0 0 -0.785398163397464" xyz="0.537047851449455 -2.06195108550525 -0.202629369887631"/>
    <parent link="base_link"/>
    <child link="pwr_link"/>
    <axis xyz="0 0 0"/>
  </joint>
  <link name="pc_link">
    <inertial>
      <origin rpy="0 0 0" xyz="0.0900000000000007 0.0899999999999996 0.0549999999999987"/>
      <mass value="3.564"/>
      <inertia ixx="0.0132165" ixy="2.16840434497101E-18" ixz="4.48566380417753E-17" iyy="0.0132165" iyz="3.91188156878236E-17" izz="0.0192456"/>
    </inertial>
    <visual>
      <origin rpy="0 0 0" xyz="0 0 0"/>
      <geometry>
        <mesh filename="package://agv_arm/meshes/pc_link.STL"/>
      </geometry>
      <material name="">
        <color rgba="1 1 1 1"/>
      </material>
    </visual>
    <collision>
      <origin rpy="0 0 0" xyz="0 0 0"/>
      <geometry>
        <mesh filename="package://agv_arm/meshes/pc_link.STL"/>
      </geometry>
    </collision>
  </link>
  <joint name="pc_joint" type="fixed">
    <origin rpy="0 0 -0.785398163397444" xyz="0.443428957278179 -1.8856571096602 -0.202629369887629"/>
    <parent link="base_link"/>
    <child link="pc_link"/>
    <axis xyz="0 0 0"/>
  </joint>
  <link name="arm_base_link">
    <inertial>
      <origin rpy="0 0 0" xyz="0.00490052804003338 -0.00481017320563648 -0.021066541781232"/>
      <mass value="0.186287727416132"/>
      <inertia ixx="0.000289688079345907" ixy="2.81201318343738E-05" ixz="1.49660636248942E-06" iyy="0.00029261821718986" iyz="-1.97623307664118E-06" izz="0.000520691140482188"/>
    </inertial>
    <visual>
      <origin rpy="0 0 0" xyz="0 0 0"/>
      <geometry>
        <mesh filename="package://agv_arm/meshes/arm_base_link.STL"/>
      </geometry>
      <material name="">
        <color rgba="1 1 1 1"/>
      </material>
    </visual>
    <collision>
      <origin rpy="0 0 0" xyz="0 0 0"/>
      <geometry>
        <mesh filename="package://agv_arm/meshes/arm_base_link.STL"/>
      </geometry>
    </collision>
  </link>
  <joint name="arm_base_joint" type="fixed">
    <origin rpy="0 0 0.785398163397444" xyz="0.0900000000000019 0.0900000000000007 0.148999999999999"/>
    <parent link="pc_link"/>
    <child link="arm_base_link"/>
    <axis xyz="0 0 0"/>
  </joint>
  <link name="link1">
    <inertial>
      <origin rpy="0 0 0" xyz="-0.0580836115244474 -0.00236345578723585 3.37147547622152E-05"/>
      <mass value="1.61405847784087"/>
      <inertia ixx="0.00291567801316754" ixy="-3.39495643450864E-05" ixz="3.86124786793899E-06" iyy="0.00431965883928423" iyz="-2.13734994359421E-07" izz="0.0043496458043079"/>
    </inertial>
    <visual>
      <origin rpy="0 0 0" xyz="0 0 0"/>
      <geometry>
        <mesh filename="package://agv_arm/meshes/link1.STL"/>
      </geometry>
      <material name="">
        <color rgba="0.752941176470588 0.752941176470588 0.752941176470588 1"/>
      </material>
    </visual>
    <collision>
      <origin rpy="0 0 0" xyz="0 0 0"/>
      <geometry>
        <mesh filename="package://agv_arm/meshes/link1.STL"/>
      </geometry>
    </collision>
  </link>
  <joint name="joint1" type="revolute">
    <origin rpy="2.3562 1.5708 0" xyz="0 0 0.0147"/>
    <parent link="arm_base_link"/>
    <child link="link1"/>
    <axis xyz="-1 0 0"/>
    <limit effort="1" lower="-11" upper="11" velocity="1"/>
  </joint>
  <link name="link2">
    <inertial>
      <origin rpy="0 0 0" xyz="-0.058443072043219 -0.187149982610973 8.10917333282646E-10"/>
      <mass value="3.791948779547"/>
      <inertia ixx="0.12031941503411" ixy="-4.02923389005563E-07" ixz="-8.3128712247138E-12" iyy="0.00991248720502792" iyz="-2.05172273895114E-05" izz="0.123189953162704"/>
    </inertial>
    <visual>
      <origin rpy="0 0 0" xyz="0 0 0"/>
      <geometry>
        <mesh filename="package://agv_arm/meshes/link2.STL"/>
      </geometry>
      <material name="">
        <color rgba="0.752941176470588 0.752941176470588 0.752941176470588 1"/>
      </material>
    </visual>
    <collision>
      <origin rpy="0 0 0" xyz="0 0 0"/>
      <geometry>
        <mesh filename="package://agv_arm/meshes/link2.STL"/>
      </geometry>
    </collision>
  </link>
  <joint name="joint2" type="revolute">
    <origin rpy="-3.1411 0 1.5708" xyz="-0.0605 -0.0774 0"/>
    <parent link="link1"/>
    <child link="link2"/>
    <axis xyz="-1 0 0"/>
    <limit effort="1" lower="-11" upper="11" velocity="1"/>
  </joint>
  <link name="link3">
    <inertial>
      <origin rpy="0 0 0" xyz="0.00327690020152471 0.230716519226641 -4.09806422019265E-06"/>
      <mass value="1.56494299506339"/>
      <inertia ixx="0.0317706162407526" ixy="0.00116167025812189" ixz="-2.34389404700323E-07" iyy="0.00289552973549577" iyz="8.33772344867732E-07" izz="0.0324540099023521"/>
    </inertial>
    <visual>
      <origin rpy="0 0 0" xyz="0 0 0"/>
      <geometry>
        <mesh filename="package://agv_arm/meshes/link3.STL"/>
      </geometry>
      <material name="">
        <color rgba="1 1 1 1"/>
      </material>
    </visual>
    <collision>
      <origin rpy="0 0 0" xyz="0 0 0"/>
      <geometry>
        <mesh filename="package://agv_arm/meshes/link3.STL"/>
      </geometry>
    </collision>
  </link>
  <joint name="joint3" type="revolute">
    <origin rpy="-0.5236 0 -3.1416" xyz="0.0776 -0.3743 0"/>
    <parent link="link2"/>
    <child link="link3"/>
    <axis xyz="1 0 0"/>
    <limit effort="1" lower="-11" upper="11" velocity="1"/>
  </joint>
  <link name="link4">
    <inertial>
      <origin rpy="0 0 0" xyz="0.11561 5.7097E-05 -0.00018258"/>
      <mass value="0.84041"/>
      <inertia ixx="0.0015998" ixy="-1.1435E-06" ixz="3.8465E-06" iyy="0.0015497" iyz="0.00017286" izz="0.00094873"/>
    </inertial>
    <visual>
      <origin rpy="0 0 0" xyz="0 0 0"/>
      <geometry>
        <mesh filename="package://agv_arm/meshes/link4.STL"/>
      </geometry>
      <material name="">
        <color rgba="1 1 1 1"/>
      </material>
    </visual>
    <collision>
      <origin rpy="0 0 0" xyz="0 0 0"/>
      <geometry>
        <mesh filename="package://agv_arm/meshes/link4.STL"/>
      </geometry>
    </collision>
  </link>
  <joint name="joint4" type="revolute">
    <origin rpy="0.52406 0 0" xyz="-0.0023 0.343 0"/>
    <parent link="link3"/>
    <child link="link4"/>
    <axis xyz="-1 0 0"/>
    <limit effort="1" lower="-11" upper="11" velocity="1"/>
  </joint>
  <link name="link5">
    <inertial>
      <origin rpy="0 0 0" xyz="0.115612522026538 -7.97844709499174E-06 0.000191136766434452"/>
      <mass value="0.840412058075631"/>
      <inertia ixx="0.00159982898122317" ixy="1.09937156347989E-07" ixz="-4.011756874856E-06" iyy="0.00159587978369747" iyz="-2.27476393969435E-07" izz="0.000902559738954227"/>
    </inertial>
    <visual>
      <origin rpy="0 0 0" xyz="0 0 0"/>
      <geometry>
        <mesh filename="package://agv_arm/meshes/link5.STL"/>
      </geometry>
      <material name="">
        <color rgba="1 1 1 1"/>
      </material>
    </visual>
    <collision>
      <origin rpy="0 0 0" xyz="0 0 0"/>
      <geometry>
        <mesh filename="package://agv_arm/meshes/link5.STL"/>
      </geometry>
    </collision>
  </link>
  <joint name="joint5" type="revolute">
    <origin rpy="1.5708 1.3095 1.5708" xyz="0.117 -0.00059425 0.0022219"/>
    <parent link="link4"/>
    <child link="link5"/>
    <axis xyz="-1 0 0"/>
    <limit effort="1" lower="-11" upper="11" velocity="1"/>
  </joint>
  <link name="link6">
    <inertial>
      <origin rpy="0 0 0" xyz="0.0937284093899606 0.00125643016528976 -0.00340032585429439"/>
      <mass value="0.0668194609592444"/>
      <inertia ixx="5.23286445076854E-05" ixy="-2.75892558766107E-07" ixz="7.6426085456963E-06" iyy="9.37815768650153E-05" iyz="-5.05869329356398E-08" izz="9.75627483530319E-05"/>
    </inertial>
    <visual>
      <origin rpy="0 0 0" xyz="0 0 0"/>
      <geometry>
        <mesh filename="package://agv_arm/meshes/link6.STL"/>
      </geometry>
      <material name="">
        <color rgba="1 1 1 1"/>
      </material>
    </visual>
    <collision>
      <origin rpy="0 0 0" xyz="0 0 0"/>
      <geometry>
        <mesh filename="package://agv_arm/meshes/link6.STL"/>
      </geometry>
    </collision>
  </link>
  <joint name="joint6" type="revolute">
    <origin rpy="2.4586 1.5708 0" xyz="0.1172 0.0011441 0.20381"/>
    <parent link="link5"/>
    <child link="link6"/>
    <axis xyz="1 0 0"/>
    <limit effort="1" lower="-11" upper="11" velocity="1"/>
  </joint>
  <link name="d415_link">
    <inertial>
      <origin rpy="0 0 0" xyz="-8.80002689940262E-06 -0.0111114286769174 -0.00437440361856423"/>
      <mass value="0.0164396913357332"/>
      <inertia ixx="1.36517854018282E-06" ixy="-1.4832961618019E-11" ixz="1.86196491500686E-09" iyy="1.29701074407964E-05" iyz="-4.4074672358564E-08" izz="1.31174062505006E-05"/>
    </inertial>
    <visual>
      <origin rpy="0 0 0" xyz="0 0 0"/>
      <geometry>
        <mesh filename="package://agv_arm/meshes/d415_link.STL"/>
      </geometry>
      <material name="">
        <color rgba="1 1 1 1"/>
      </material>
    </visual>
    <collision>
      <origin rpy="0 0 0" xyz="0 0 0"/>
      <geometry>
        <mesh filename="package://agv_arm/meshes/d415_link.STL"/>
      </geometry>
    </collision>
  </link>
  <joint name="d415_joint" type="fixed">
    <origin rpy="1.5708 0 -1.5708" xyz="0.12161 0.0010118 -0.044069"/>
    <parent link="link6"/>
    <child link="d415_link"/>
    <axis xyz="0 0 0"/>
  </joint>
  <link name="end_Link">
    <inertial>
      <origin rpy="0 0 0" xyz="-1.6194E-12 -1.1574E-12 -0.058025"/>
      <mass value="0.017438"/>
      <inertia ixx="2.612E-06" ixy="-3.3357E-16" ixz="1.5154E-16" iyy="3.7889E-06" iyz="1.0639E-16" izz="5.2919E-06"/>
    </inertial>
    <visual>
      <origin rpy="0 0 0" xyz="0 0 0"/>
      <geometry>
        <mesh filename="package://agv_arm/meshes/end_Link.STL"/>
      </geometry>
      <material name="">
        <color rgba="1 1 1 1"/>
      </material>
    </visual>
    <collision>
      <origin rpy="0 0 0" xyz="0 0 0"/>
      <geometry>
        <mesh filename="package://agv_arm/meshes/end_Link.STL"/>
      </geometry>
    </collision>
  </link>
  <joint name="end_joint" type="fixed">
    <origin rpy="-1.5708 0 -1.5708" xyz="0.098859 0.0008176 -0.00037218"/>
    <parent link="link6"/>
    <child link="end_Link"/>
    <axis xyz="0 0 0"/>
  </joint>
  <link name="finger_link2">
    <inertial>
      <origin rpy="0 0 0" xyz="0.0187104737539545 -0.0153951860375225 -0.000375520770545368"/>
      <mass value="0.00520135161584462"/>
      <inertia ixx="1.83812760924892E-07" ixy="2.06102890915583E-08" ixz="2.81175606698671E-10" iyy="1.74961047766003E-06" iyz="7.48427007720244E-11" izz="1.6907528168377E-06"/>
    </inertial>
    <visual>
      <origin rpy="0 0 0" xyz="0 0 0"/>
      <geometry>
        <mesh filename="package://agv_arm/meshes/finger_link2.STL"/>
      </geometry>
      <material name="">
        <color rgba="1 1 1 1"/>
      </material>
    </visual>
    <collision>
      <origin rpy="0 0 0" xyz="0 0 0"/>
      <geometry>
        <mesh filename="package://agv_arm/meshes/finger_link2.STL"/>
      </geometry>
    </collision>
  </link>
  <joint name="finger_joint2" type="prismatic">
    <origin rpy="1.5708 -1.5708 0" xyz="0.0008176 -0.00037218 -0.098859"/>
    <parent link="end_Link"/>
    <child link="finger_link2"/>
    <axis xyz="0 -1 0"/>
    <limit effort="1" lower="-0.1" upper="0.1" velocity="1"/>
  </joint>
  <link name="finger_link1">
    <inertial>
      <origin rpy="0 0 0" xyz="0.0187104737539552 0.0170303895104817 -0.000368846804288392"/>
      <mass value="0.0052013516158447"/>
      <inertia ixx="1.83812760924895E-07" ixy="-2.06102890915209E-08" ixz="-2.81175606748554E-10" iyy="1.74961047766009E-06" iyz="7.48427007708597E-11" izz="1.69075281683777E-06"/>
    </inertial>
    <visual>
      <origin rpy="0 0 0" xyz="0 0 0"/>
      <geometry>
        <mesh filename="package://agv_arm/meshes/finger_link1.STL"/>
      </geometry>
      <material name="">
        <color rgba="1 1 1 1"/>
      </material>
    </visual>
    <collision>
      <origin rpy="0 0 0" xyz="0 0 0"/>
      <geometry>
        <mesh filename="package://agv_arm/meshes/finger_link1.STL"/>
      </geometry>
    </collision>
  </link>
  <joint name="finger_joint1" type="prismatic">
    <origin rpy="1.5708 -1.5708 0" xyz="0.0008176 -0.00037218 -0.098859"/>
    <parent link="end_Link"/>
    <child link="finger_link1"/>
    <axis xyz="0 -1 0"/>
    <limit effort="1" lower="-0.1" upper="0.1" velocity="1"/>
  </joint>
  <link name="front_link1">
    <inertial>
      <origin rpy="0 0 0" xyz="0.00454938714218511 -0.015085259662572 -0.000170656801913083"/>
      <mass value="0.034500655949196"/>
      <inertia ixx="2.12981416033846E-05" ixy="5.75050325361881E-06" ixz="-2.10334644621655E-08" iyy="1.1496091748026E-05" iyz="4.74056732385173E-08" izz="2.38494390827886E-05"/>
    </inertial>
    <visual>
      <origin rpy="0 0 0" xyz="0 0 0"/>
      <geometry>
        <mesh filename="package://agv_arm/meshes/front_link1.STL"/>
      </geometry>
      <material name="">
        <color rgba="1 1 1 1"/>
      </material>
    </visual>
    <collision>
      <origin rpy="0 0 0" xyz="0 0 0"/>
      <geometry>
        <mesh filename="package://agv_arm/meshes/front_link1.STL"/>
      </geometry>
    </collision>
  </link>
  <joint name="front_joint1" type="revolute">
    <origin rpy="1.5708 0 -2.348" xyz="0.4146 -1.7543 -0.34847"/>
    <parent link="base_link"/>
    <child link="front_link1"/>
    <axis xyz="0 -1 0"/>
    <limit effort="1" lower="-11" upper="11" velocity="1"/>
  </joint>
  <link name="front_link2">
    <inertial>
      <origin rpy="0 0 0" xyz="-0.0124999976229834 -9.50171608060657E-11 -6.94045200200222E-08"/>
      <mass value="0.0687071234614241"/>
      <inertia ixx="2.95185233018021E-05" ixy="-7.42208136188817E-12" ixz="2.12622845609782E-12" iyy="1.83159672228595E-05" iyz="-1.34415464249044E-12" izz="1.83150441372356E-05"/>
    </inertial>
    <visual>
      <origin rpy="0 0 0" xyz="0 0 0"/>
      <geometry>
        <mesh filename="package://agv_arm/meshes/front_link2.STL"/>
      </geometry>
      <material name="">
        <color rgba="1 1 1 1"/>
      </material>
    </visual>
    <collision>
      <origin rpy="0 0 0" xyz="0 0 0"/>
      <geometry>
        <mesh filename="package://agv_arm/meshes/front_link2.STL"/>
      </geometry>
    </collision>
  </link>
  <joint name="front_joint2" type="revolute">
    <origin rpy="0 1.5626 0" xyz="0.021029 -0.06 -0.012535"/>
    <parent link="front_link1"/>
    <child link="front_link2"/>
    <axis xyz="1 0 0"/>
    <limit effort="1" lower="-11" upper="11" velocity="1"/>
  </joint>
  <link name="back_link1">
    <inertial>
      <origin rpy="0 0 0" xyz="-0.00346069454949682 -0.0150852596625721 0.00297090233373076"/>
      <mass value="0.0345006559491962"/>
      <inertia ixx="2.25737904320763E-05" ixy="-4.06635819984328E-06" ixz="1.27582213248182E-06" iyy="1.1496091748026E-05" iyz="4.06635782467598E-06" izz="2.25737902540973E-05"/>
    </inertial>
    <visual>
      <origin rpy="0 0 0" xyz="0 0 0"/>
      <geometry>
        <mesh filename="package://agv_arm/meshes/back_link1.STL"/>
      </geometry>
      <material name="">
        <color rgba="1 1 1 1"/>
      </material>
    </visual>
    <collision>
      <origin rpy="0 0 0" xyz="0 0 0"/>
      <geometry>
        <mesh filename="package://agv_arm/meshes/back_link1.STL"/>
      </geometry>
    </collision>
  </link>
  <joint name="back_joint1" type="revolute">
    <origin rpy="1.5708 0 0" xyz="0.72612 -2.0163 -0.34847"/>
    <parent link="base_link"/>
    <child link="back_link1"/>
    <axis xyz="0 -1 0"/>
    <limit effort="1" lower="-11" upper="11" velocity="1"/>
  </joint>
  <link name="back_link2">
    <inertial>
      <origin rpy="0 0 0" xyz="0.0125000023770157 -9.50173828506706E-11 -6.94045209082006E-08"/>
      <mass value="0.0687071234614254"/>
      <inertia ixx="2.9518523301803E-05" ixy="-7.42208142249208E-12" ixz="2.12622844932155E-12" iyy="1.83159672228599E-05" iyz="-1.34415462039289E-12" izz="1.83150441372361E-05"/>
    </inertial>
    <visual>
      <origin rpy="0 0 0" xyz="0 0 0"/>
      <geometry>
        <mesh filename="package://agv_arm/meshes/back_link2.STL"/>
      </geometry>
      <material name="">
        <color rgba="1 1 1 1"/>
      </material>
    </visual>
    <collision>
      <origin rpy="0 0 0" xyz="0 0 0"/>
      <geometry>
        <mesh filename="package://agv_arm/meshes/back_link2.STL"/>
      </geometry>
    </collision>
  </link>
  <joint name="back_joint2" type="revolute">
    <origin rpy="0 -0.7854 0" xyz="-0.02388 -0.06 0.0057124"/>
    <parent link="back_link1"/>
    <child link="back_link2"/>
    <axis xyz="1 0 0"/>
    <limit effort="1" lower="-11" upper="11" velocity="1"/>
  </joint>
  <!-- TEST -->
  <!-- camera body, with origin at bottom screw mount -->
  <joint name="d435_joint" type="fixed">
    <origin rpy="0 -1.570 1.570 " xyz="0 0 0.0"/>
    <parent link="d415_link"/>
    <child link="d435_bottom_screw_frame"/>
  </joint>
  <link name="d435_bottom_screw_frame"/>
  <joint name="d435_link_joint" type="fixed">
    <origin rpy="0 0 0" xyz="0 0.0175 0.0125"/>
    <parent link="d435_bottom_screw_frame"/>
    <child link="d435_link"/>
  </joint>
  <link name="d435_link">
    <visual>
      <origin rpy="1.57079632679 0 1.57079632679" xyz="0.0149 -0.0175 0"/>
      <geometry>
        <mesh filename="package://realsense_ros_gazebo/meshes/realsense_d435.stl"/>
      </geometry>
    </visual>
    <collision>
      <origin rpy="0 0 0" xyz="0 -0.0175 0"/>
      <geometry>
        <box size="0.02505 0.09 0.025"/>
      </geometry>
    </collision>
    <inertial>
      <mass value="0.564"/>
      <origin rpy="0 0 0" xyz="0 -0.0175 0"/>
      <inertia ixx="0.000410075" ixy="0" ixz="0" iyy="5.88676175e-05" iyz="0" izz="5.88676175e-05"/>
    </inertial>
  </link>
  <!-- camera depth joints and links -->
  <joint name="d435_depth_joint" type="fixed">
    <origin rpy="0 0 0" xyz="0 0 0"/>
    <parent link="d435_link"/>
    <child link="d435_depth_frame"/>
  </joint>
  <link name="d435_depth_frame"/>
  <joint name="d435_depth_optical_joint" type="fixed">
    <origin rpy="-1.57079632679 0 -1.57079632679" xyz="0 0 0"/>
    <parent link="d435_depth_frame"/>
    <child link="d435_depth_optical_frame"/>
  </joint>
  <link name="d435_depth_optical_frame"/>
  <!-- camera left IR joints and links -->
  <joint name="d435_left_ir_joint" type="fixed">
    <origin rpy="0 0 0" xyz="0 0.0 0"/>
    <parent link="d435_depth_frame"/>
    <child link="d435_left_ir_frame"/>
  </joint>
  <link name="d435_left_ir_frame"/>
  <joint name="d435_left_ir_optical_joint" type="fixed">
    <origin rpy="-1.57079632679 0 -1.57079632679" xyz="0 0 0"/>
    <parent link="d435_left_ir_frame"/>
    <child link="d435_left_ir_optical_frame"/>
  </joint>
  <link name="d435_left_ir_optical_frame"/>
  <!-- camera right IR joints and links -->
  <joint name="d435_right_ir_joint" type="fixed">
    <origin rpy="0 0 0" xyz="0 -0.05 0"/>
    <parent link="d435_depth_frame"/>
    <child link="d435_right_ir_frame"/>
  </joint>
  <link name="d435_right_ir_frame"/>
  <joint name="d435_right_ir_optical_joint" type="fixed">
    <origin rpy="-1.57079632679 0 -1.57079632679" xyz="0 0 0"/>
    <parent link="d435_right_ir_frame"/>
    <child link="d435_right_ir_optical_frame"/>
  </joint>
  <link name="d435_right_ir_optical_frame"/>
  <!-- camera color joints and links -->
  <joint name="d435_color_joint" type="fixed">
    <origin rpy="0 0 0" xyz="0 0.015 0"/>
    <parent link="d435_depth_frame"/>
    <child link="d435_color_frame"/>
  </joint>
  <link name="d435_color_frame"/>
  <joint name="d435_color_optical_joint" type="fixed">
    <origin rpy="-1.57079632679 0 -1.57079632679" xyz="0 0 0"/>
    <parent link="d435_color_frame"/>
    <child link="d435_color_optical_frame"/>
  </joint>
  <link name="d435_color_optical_frame"/>
  <!-- gazebo plugin -->
  <gazebo reference="d435_link">
    <self_collide>0</self_collide>
    <enable_wind>0</enable_wind>
    <kinematic>0</kinematic>
    <gravity>1</gravity>
    <mu2>1</mu2>
    <fdir1>0 0 0</fdir1>
    <kp>1e+13</kp>
    <kd>1</kd>
    <sensor name="d435_color" type="camera">
      <camera name="d435">
        <horizontal_fov>1.21125850088</horizontal_fov>
        <image>
          <width>640</width>
          <height>480</height>
          <format>RGB_INT8</format>
        </image>
        <clip>
          <near>0.1</near>
          <far>100</far>
        </clip>
        <noise>
          <type>gaussian</type>
          <mean>0.0</mean>
          <stddev>0.007</stddev>
        </noise>
      </camera>
      <always_on>1</always_on>
      <update_rate>30</update_rate>
      <visualize>1</visualize>
    </sensor>
    <sensor name="d435_ired1" type="camera">
      <camera name="d435">
        <horizontal_fov>1.4870205227</horizontal_fov>
        <image>
          <width>1280</width>
          <height>720</height>
          <format>L_INT8</format>
        </image>
        <clip>
          <near>0.1</near>
          <far>100</far>
        </clip>
        <noise>
          <type>gaussian</type>
          <mean>0.0</mean>
          <stddev>0.05</stddev>
        </noise>
      </camera>
      <always_on>1</always_on>
      <update_rate>90</update_rate>
      <visualize>0</visualize>
    </sensor>
    <sensor name="d435_ired2" type="camera">
      <camera name="d435">
        <horizontal_fov>1.4870205227</horizontal_fov>
        <image>
          <width>1280</width>
          <height>720</height>
          <format>L_INT8</format>
        </image>
        <clip>
          <near>0.1</near>
          <far>100</far>
        </clip>
        <noise>
          <type>gaussian</type>
          <mean>0.0</mean>
          <stddev>0.05</stddev>
        </noise>
      </camera>
      <always_on>1</always_on>
      <update_rate>90</update_rate>
      <visualize>0</visualize>
    </sensor>
    <sensor name="d435_depth" type="depth">
      <camera name="d435">
        <horizontal_fov>1.4870205227</horizontal_fov>
        <image>
          <width>1280</width>
          <height>720</height>
        </image>
        <clip>
          <near>0.1</near>
          <far>100</far>
        </clip>
        <noise>
          <type>gaussian</type>
          <mean>0.0</mean>
          <stddev>0.100</stddev>
        </noise>
      </camera>
      <always_on>1</always_on>
      <update_rate>90</update_rate>
      <visualize>0</visualize>
    </sensor>
  </gazebo>
  <gazebo>
    <plugin filename="librealsense_gazebo_plugin.so" name="d435">
      <prefix>d435_</prefix>
      <depthUpdateRate>10</depthUpdateRate>
      <colorUpdateRate>10</colorUpdateRate>
      <infraredUpdateRate>10</infraredUpdateRate>
      <depthTopicName>depth/image_raw</depthTopicName>
      <depthCameraInfoTopicName>depth/camera_info</depthCameraInfoTopicName>
      <colorTopicName>color/image_raw</colorTopicName>
      <colorCameraInfoTopicName>color/camera_info</colorCameraInfoTopicName>
      <infrared1TopicName>infra1/image_raw</infrared1TopicName>
      <infrared1CameraInfoTopicName>infra1/camera_info</infrared1CameraInfoTopicName>
      <infrared2TopicName>infra2/image_raw</infrared2TopicName>
      <infrared2CameraInfoTopicName>infra2/camera_info</infrared2CameraInfoTopicName>
      <colorOpticalframeName>d435_color_optical_frame</colorOpticalframeName>
      <depthOpticalframeName>d435_depth_optical_frame</depthOpticalframeName>
      <infrared1OpticalframeName>d435_infrared1_optical_frame</infrared1OpticalframeName>
      <infrared2OpticalframeName>d435_infrared2_optical_frame</infrared2OpticalframeName>
      <rangeMinDepth>0.2</rangeMinDepth>
      <rangeMaxDepth>10.0</rangeMaxDepth>
      <pointCloud>false</pointCloud>
      <pointCloudTopicName>depth/color/points</pointCloudTopicName>
      <pointCloudCutoff>0.25</pointCloudCutoff>
      <pointCloudCutoffMax>9.0</pointCloudCutoffMax>
    </plugin>
  </gazebo>
</robot>

