<?xml version="1.0" encoding="utf-8"?>
<!-- =================================================================================== -->
<!-- |    This document was autogenerated by xacro from test_agv_arm.xacro             | -->
<!-- |    EDITING THIS FILE BY HAND IS NOT RECOMMENDED                                 | -->
<!-- =================================================================================== -->
<robot name="test_model">
  <!-- T265 Fisheye:

  gazebo_ros_camera supports only plumb_bob
  D: [-0.007419134024530649, 0.041209351271390915, -0.03811917081475258, 0.006366158835589886, 0.0]

  <distortionK1>-0.007419134024530649</distortionK1>
  <distortionK2>0.041209351271390915</distortionK2>
  <distortionK3>-0.03811917081475258</distortionK3>
  <distortionT1>0.006366158835589886</distortionT1>
  <distortionT2>0.0</distortionT2>

       [fx'  0  cx' Tx]
   P = [ 0  fy' cy' Ty]
       [ 0   0   1   0]

   P : [ 285.5480041503906, 0.0, 416.00531005859375, 0.0,
         0.0, 285.3793029785156, 403.38909912109375, 0.0,
         0.0, 0.0, 1.0, 0.0 ]

  <CxPrime>416.00531005859375</CxPrime>

       [fx  0 cx]
   K = [ 0 fy cy]
       [ 0  0  1]

   K : [ 285.5480041503906, 0.0, 416.00531005859375,
         0.0, 285.3793029785156, 403.38909912109375,
         0.0, 0.0, 1.0]

  <Cx>16.00531005859375</Cx>
  <Cy>403.38909912109375</Cy>

  -->
  <!-- INTEL REALSENSE T265 -->
  <!-- INTEL REALSENSE D435 -->
  <!-- INTEL REALSENSE R200 -->
  <link name="virtual_link">
    </link>
  <joint name="virtual_joint" type="fixed">
    <origin rpy="0 0 0" xyz="0. 0. 0."/>
    <parent link="virtual_link"/>
    <child link="base_link"/>
    <axis xyz="0 0 0"/>
  </joint>
  <link name="base_link">
    <inertial>
      <origin rpy="0 0 0" xyz="0.570341970178263 -1.88528825872454 -0.303668536274056"/>
      <mass value="15.35773705728221"/>
      <inertia ixx="0.0789888195141757" ixy="0.0296735251325005" ixz="6.86804058744454E-05" iyy="0.0636306474316625" iyz="-6.67380007365903E-05" izz="0.111507797834734"/>
    </inertial>
    <visual>
      <origin rpy="0 0 0" xyz="0 0 0"/>
      <geometry>
        <mesh filename="package://agv_arm/meshes/base_link.STL"/>
      </geometry>
      <material name="">
        <color rgba="1 1 1 1"/>
      </material>
    </visual>
    <collision>
      <origin rpy="0 0 0" xyz="0 0 0"/>
      <geometry>
        <mesh filename="package://agv_arm/meshes/base_link.STL"/>
      </geometry>
    </collision>
  </link>
  <link name="left_link">
    <inertial>
      <origin rpy="0 0 0" xyz="-3.35147465335695E-11 -2.9989711491929E-08 -0.00348654259039582"/>
      <mass value="1.04303512282038"/>
      <inertia ixx="0.00314520431907286" ixy="-1.69296163459592E-13" ixz="1.16373146619381E-08" iyy="0.00314538157747688" iyz="7.37806581238218E-11" izz="0.00586701765374411"/>
    </inertial>
    <visual>
      <origin rpy="0 0 0" xyz="0 0 0"/>
      <geometry>
        <mesh filename="package://agv_arm/meshes/left_link.STL"/>
      </geometry>
      <material name="">
        <color rgba="1 1 1 1"/>
      </material>
    </visual>
    <collision>
      <origin rpy="0 0 0" xyz="0 0 0"/>
      <geometry>
        <mesh filename="package://agv_arm/meshes/left_link.STL"/>
      </geometry>
    </collision>
  </link>
  <joint name="left_joint" type="revolute">
    <origin rpy="1.5707963267949 -0.0872664625997168 -0.785398163397436" xyz="0.453993383404549 -2.00158044618336 -0.34097136988763"/>
    <parent link="base_link"/>
    <child link="left_link"/>
    <axis xyz="0 0 -1"/>
    <limit effort="1" lower="-1" upper="1" velocity="1"/>
  </joint>
  <link name="right_link">
    <inertial>
      <origin rpy="0 0 0" xyz="-3.35149685781744E-11 -2.99897112143732E-08 -0.00348654259039594"/>
      <mass value="1.04303512282037"/>
      <inertia ixx="0.00314520431907283" ixy="-1.69297681342634E-13" ixz="1.16373147203766E-08" iyy="0.00314538157747685" iyz="7.37806865299187E-11" izz="0.00586701765374405"/>
    </inertial>
    <visual>
      <origin rpy="0 0 0" xyz="0 0 0"/>
      <geometry>
        <mesh filename="package://agv_arm/meshes/right_link.STL"/>
      </geometry>
      <material name="">
        <color rgba="1 1 1 1"/>
      </material>
    </visual>
    <collision>
      <origin rpy="0 0 0" xyz="0 0 0"/>
      <geometry>
        <mesh filename="package://agv_arm/meshes/right_link.STL"/>
      </geometry>
    </collision>
  </link>
  <joint name="right_joint" type="revolute">
    <origin rpy="1.5707963267949 -0.0872664625997167 2.35619449019234" xyz="0.686631514414924 -1.76894231517299 -0.340971369887628"/>
    <parent link="base_link"/>
    <child link="right_link"/>
    <axis xyz="0 0 -1"/>
    <limit effort="1" lower="-1" upper="1" velocity="1"/>
  </joint>
  <link name="lidar_link">
    <inertial>
      <origin rpy="0 0 0" xyz="-0.000296153234327745 1.12836329169141E-09 -0.0204717812660532"/>
      <mass value="0.131588919004472"/>
      <inertia ixx="7.14622431639405E-05" ixy="3.31964390668676E-12" ixz="8.65350822911068E-07" iyy="7.23109738477428E-05" iyz="-2.4711482954829E-12" izz="4.46765670225869E-05"/>
    </inertial>
    <visual>
      <origin rpy="0 0 0" xyz="0 0 0"/>
      <geometry>
        <mesh filename="package://agv_arm/meshes/lidar_link.STL"/>
      </geometry>
      <material name="">
        <color rgba="1 1 1 1"/>
      </material>
    </visual>
    <collision>
      <origin rpy="0 0 0" xyz="0 0 0"/>
      <geometry>
        <mesh filename="package://agv_arm/meshes/lidar_link.STL"/>
      </geometry>
    </collision>
  </link>
  <joint name="lidar_joint" type="fixed">
    <origin rpy="0 0 2.35619449021312" xyz="0.392951119656292 -1.70790005142473 -0.152629369887627"/>
    <parent link="base_link"/>
    <child link="lidar_link"/>
    <axis xyz="0 0 0"/>
  </joint>
  <link name="pwr_link">
    <inertial>
      <origin rpy="0 0 0" xyz="0.0149998988087228 0.0149999922703186 0.0302002587155129"/>
      <mass value="0.0494935351719684"/>
      <inertia ixx="2.25637713562706E-05" ixy="1.12310101294322E-11" ixz="1.59879773971505E-10" iyy="2.25636840533923E-05" iyz="1.00765741349493E-11" izz="6.57719217809585E-06"/>
    </inertial>
    <visual>
      <origin rpy="0 0 0" xyz="0 0 0"/>
      <geometry>
        <mesh filename="package://agv_arm/meshes/pwr_link.STL"/>
      </geometry>
      <material name="">
        <color rgba="1 1 1 1"/>
      </material>
    </visual>
    <collision>
      <origin rpy="0 0 0" xyz="0 0 0"/>
      <geometry>
        <mesh filename="package://agv_arm/meshes/pwr_link.STL"/>
      </geometry>
    </collision>
  </link>
  <joint name="pwr_joint" type="fixed">
    <origin rpy="0 0 -0.785398163397464" xyz="0.537047851449455 -2.06195108550525 -0.202629369887631"/>
    <parent link="base_link"/>
    <child link="pwr_link"/>
    <axis xyz="0 0 0"/>
  </joint>
  <link name="pc_link">
    <inertial>
      <origin rpy="0 0 0" xyz="0.0900000000000007 0.0899999999999996 0.0549999999999987"/>
      <mass value="3.564"/>
      <inertia ixx="0.0132165" ixy="2.16840434497101E-18" ixz="4.48431349330871E-17" iyy="0.0132165" iyz="3.91188156878237E-17" izz="0.0192456"/>
    </inertial>
    <visual>
      <origin rpy="0 0 0" xyz="0 0 0"/>
      <geometry>
        <mesh filename="package://agv_arm/meshes/pc_link.STL"/>
      </geometry>
      <material name="">
        <color rgba="1 1 1 1"/>
      </material>
    </visual>
    <collision>
      <origin rpy="0 0 0" xyz="0 0 0"/>
      <geometry>
        <mesh filename="package://agv_arm/meshes/pc_link.STL"/>
      </geometry>
    </collision>
  </link>
  <joint name="pc_joint" type="fixed">
    <origin rpy="0 0 -0.785398163397444" xyz="0.443428957278179 -1.8856571096602 -0.202629369887629"/>
    <parent link="base_link"/>
    <child link="pc_link"/>
    <axis xyz="0 0 0"/>
  </joint>
  <link name="arm_base_link">
    <inertial>
      <origin rpy="0 0 0" xyz="0.00490052804003327 -0.00481017320563626 -0.021066541781232"/>
      <mass value="0.186287727416132"/>
      <inertia ixx="0.000289688079345907" ixy="2.81201318343738E-05" ixz="1.49660636248943E-06" iyy="0.00029261821718986" iyz="-1.97623307664118E-06" izz="0.000520691140482188"/>
    </inertial>
    <visual>
      <origin rpy="0 0 0" xyz="0 0 0"/>
      <geometry>
        <mesh filename="package://agv_arm/meshes/arm_base_link.STL"/>
      </geometry>
      <material name="">
        <color rgba="1 1 1 1"/>
      </material>
    </visual>
    <collision>
      <origin rpy="0 0 0" xyz="0 0 0"/>
      <geometry>
        <mesh filename="package://agv_arm/meshes/arm_base_link.STL"/>
      </geometry>
    </collision>
  </link>
  <joint name="arm_base_joint" type="fixed">
    <origin rpy="0 0 0.785398163397444" xyz="0.0900000000000019 0.0900000000000007 0.148999999999999"/>
    <parent link="pc_link"/>
    <child link="arm_base_link"/>
    <axis xyz="0 0 0"/>
  </joint>
  <link name="link1">
    <inertial>
      <origin rpy="0 0 0" xyz="-0.0580836115244474 -0.00236345578723585 3.37147547622152E-05"/>
      <mass value="0.0061405847784087"/>
      <inertia ixx="0.00291567801316754" ixy="-3.39495643450857E-05" ixz="3.86124786793925E-06" iyy="0.00431965883928423" iyz="-2.13734994359855E-07" izz="0.0043496458043079"/>
    </inertial>
    <visual>
      <origin rpy="0 0 0" xyz="0 0 0"/>
      <geometry>
        <mesh filename="package://agv_arm/meshes/link1.STL"/>
      </geometry>
      <material name="">
        <color rgba="0.752941176470588 0.752941176470588 0.752941176470588 1"/>
      </material>
    </visual>
    <collision>
      <origin rpy="0 0 0" xyz="0 0 0"/>
      <geometry>
        <mesh filename="package://agv_arm/meshes/link1.STL"/>
      </geometry>
    </collision>
  </link>
  <joint name="joint1" type="revolute">
    <origin rpy="2.35619449019234 1.5707963267949 0" xyz="0 0 0.0146999999999999"/>
    <parent link="arm_base_link"/>
    <child link="link1"/>
    <axis xyz="-1 0 0"/>
    <limit effort="1" lower="-1" upper="1" velocity="1"/>
  </joint>
  <link name="link2">
    <inertial>
      <origin rpy="0 0 0" xyz="-0.0584430720432187 -0.187149982610973 8.10917111238041E-10"/>
      <mass value="0.00791948779547"/>
      <inertia ixx="0.12031941503411" ixy="-4.02923389004673E-07" ixz="-8.31287816360771E-12" iyy="0.00991248720502792" iyz="-2.05172273895127E-05" izz="0.123189953162705"/>
    </inertial>
    <visual>
      <origin rpy="0 0 0" xyz="0 0 0"/>
      <geometry>
        <mesh filename="package://agv_arm/meshes/link2.STL"/>
      </geometry>
      <material name="">
        <color rgba="0.752941176470588 0.752941176470588 0.752941176470588 1"/>
      </material>
    </visual>
    <collision>
      <origin rpy="0 0 0" xyz="0 0 0"/>
      <geometry>
        <mesh filename="package://agv_arm/meshes/link2.STL"/>
      </geometry>
    </collision>
  </link>
  <joint name="joint2" type="revolute">
    <origin rpy="-3.14113476949727 0 1.5707963267949" xyz="-0.0604999999999947 -0.0773999999999913 0"/>
    <parent link="link1"/>
    <child link="link2"/>
    <axis xyz="-1 0 0"/>
    <limit effort="1" lower="-1" upper="11" velocity="1"/>
  </joint>
  <link name="link3">
    <inertial>
      <origin rpy="0 0 0" xyz="0.00327690020152493 0.230716519226641 -4.09806421997061E-06"/>
      <mass value="0.0056494299506339"/>
      <inertia ixx="0.0317706162407525" ixy="0.00116167025812186" ixz="-2.34389404698589E-07" iyy="0.00289552973549577" iyz="8.33772344844123E-07" izz="0.032454009902352"/>
    </inertial>
    <visual>
      <origin rpy="0 0 0" xyz="0 0 0"/>
      <geometry>
        <mesh filename="package://agv_arm/meshes/link3.STL"/>
      </geometry>
      <material name="">
        <color rgba="1 1 1 1"/>
      </material>
    </visual>
    <collision>
      <origin rpy="0 0 0" xyz="0 0 0"/>
      <geometry>
        <mesh filename="package://agv_arm/meshes/link3.STL"/>
      </geometry>
    </collision>
  </link>
  <joint name="joint3" type="revolute">
    <origin rpy="-0.523598775598282 0 -3.14159265358977" xyz="0.0776000000000159 -0.374299999999997 0"/>
    <parent link="link2"/>
    <child link="link3"/>
    <axis xyz="1 0 0"/>
    <limit effort="1" lower="-1" upper="1" velocity="1"/>
  </joint>
  <link name="link4">
    <inertial>
      <origin rpy="0 0 0" xyz="0.115612509083277 5.70973726401469E-05 -0.000182575257787754"/>
      <mass value="0.00840412488577877"/>
      <inertia ixx="0.0015998307768477" ixy="-1.14351554232871E-06" ixz="3.84649608459235E-06" iyy="0.00154970777246241" iyz="0.000172857355121832" izz="0.000948731553754075"/>
    </inertial>
    <visual>
      <origin rpy="0 0 0" xyz="0 0 0"/>
      <geometry>
        <mesh filename="package://agv_arm/meshes/link4.STL"/>
      </geometry>
      <material name="">
        <color rgba="1 1 1 1"/>
      </material>
    </visual>
    <collision>
      <origin rpy="0 0 0" xyz="0 0 0"/>
      <geometry>
        <mesh filename="package://agv_arm/meshes/link4.STL"/>
      </geometry>
    </collision>
  </link>
  <joint name="joint4" type="revolute">
    <origin rpy="0.524056659690805 0 0" xyz="-0.00230000000000108 0.343 0"/>
    <parent link="link3"/>
    <child link="link4"/>
    <axis xyz="-1 0 0"/>
    <limit effort="1" lower="-1" upper="1" velocity="1"/>
  </joint>
  <link name="link5">
    <inertial>
      <origin rpy="0 0 0" xyz="0.115612522026538 -7.97844709510276E-06 0.000191136766434452"/>
      <mass value="0.00140412058075631"/>
      <inertia ixx="0.00159982898122317" ixy="1.09937156347949E-07" ixz="-4.01175687485538E-06" iyy="0.00159587978369747" iyz="-2.27476393969293E-07" izz="0.000902559738954227"/>
    </inertial>
    <visual>
      <origin rpy="0 0 0" xyz="0 0 0"/>
      <geometry>
        <mesh filename="package://agv_arm/meshes/link5.STL"/>
      </geometry>
      <material name="">
        <color rgba="1 1 1 1"/>
      </material>
    </visual>
    <collision>
      <origin rpy="0 0 0" xyz="0 0 0"/>
      <geometry>
        <mesh filename="package://agv_arm/meshes/link5.STL"/>
      </geometry>
    </collision>
  </link>
  <joint name="joint5" type="revolute">
    <origin rpy="1.57079632679492 1.30945482308825 1.5707963267949" xyz="0.117 -0.000594247621558908 0.00222189083181923"/>
    <parent link="link4"/>
    <child link="link5"/>
    <axis xyz="-1 0 0"/>
    <limit effort="1" lower="-1" upper="1" velocity="1"/>
  </joint>
  <link name="link6">
    <inertial>
      <origin rpy="0 0 0" xyz="0.082781538536749 0.00116561170708307 -0.00277363175660617"/>
      <mass value="0.000842570079043402"/>
      <inertia ixx="5.77500003108311E-05" ixy="-5.96879750438297E-07" ixz="9.85758548153898E-06" iyy="0.000135210838958127" iyz="-3.22108352800688E-08" izz="0.000140044733157609"/>
    </inertial>
    <visual>
      <origin rpy="0 0 0" xyz="0 0 0"/>
      <geometry>
        <mesh filename="package://agv_arm/meshes/link6.STL"/>
      </geometry>
      <material name="">
        <color rgba="1 1 1 1"/>
      </material>
    </visual>
    <collision>
      <origin rpy="0 0 0" xyz="0 0 0"/>
      <geometry>
        <mesh filename="package://agv_arm/meshes/link6.STL"/>
      </geometry>
    </collision>
  </link>
  <joint name="joint6" type="revolute">
    <origin rpy="2.4586 1.5708 0" xyz="0.1172 0.0011441 0.20381"/>
    <parent link="link5"/>
    <child link="link6"/>
    <axis xyz="1 0 0"/>
    <limit effort="1" lower="-1" upper="1" velocity="1"/>
  </joint>
  <link name="d415_link">
    <inertial>
      <origin rpy="0 0 0" xyz="-8.80002689940262E-06 -0.0111114286769177 -0.00437440361856423"/>
      <mass value="0.0164396913357332"/>
      <inertia ixx="1.36517854018282E-06" ixy="-1.48329616184955E-11" ixz="1.86196491500615E-09" iyy="1.29701074407964E-05" iyz="-4.40746723585632E-08" izz="1.31174062505006E-05"/>
    </inertial>
    <visual>
      <origin rpy="1.57 0 1.57" xyz="0 0 0"/>
      <geometry>
        <mesh filename="package://agv_arm/meshes/d415_link.STL"/>
      </geometry>
      <material name="">
        <color rgba="1 1 1 1"/>
      </material>
    </visual>
    <collision>
      <origin rpy="0 0 0" xyz="0 0 0"/>
      <geometry>
        <mesh filename="package://agv_arm/meshes/d415_link.STL"/>
      </geometry>
    </collision>
  </link>
  <joint name="d415_joint" type="fixed">
    <!-- //// origin xyz="0.121610184391361 0.00101183482587874 -0.0440692419074167" rpy="1.5707963267949 0 -1.57079632679491" -->
    <!-- origin xyz="0.121610184391361 0.00101183482587874 -0.0440692419074167" rpy="3.1415926 1.57079632679491 1.57079632679491" -->
    <origin rpy="0 3.1415 0" xyz="0.121610184391361 0.00101183482587874 -0.0440692419074167"/>
    <parent link="link6"/>
    <child link="d415_link"/>
    <axis xyz="0 0 0"/>
  </joint>
  <!-- ////////////// D415 //////////////  -->
  <gazebo reference="d415_link">
    <sensor name="camera" type="depth">
      <always_on>true</always_on>
      <update_rate>30.0</update_rate>
      <camera>
        <horizontal_fov>1.047</horizontal_fov>
        <image>
          <format>R8G8B8</format>
          <width>640</width>
          <height>480</height>
        </image>
        <clip>
          <near>0.05</near>
          <far>8.0</far>
        </clip>
      </camera>
      <plugin filename="libgazebo_ros_openni_kinect.so" name="kinect_camera_controller">
        <cameraName>camera</cameraName>
        <alwaysOn>true</alwaysOn>
        <updateRate>30</updateRate>
        <imageTopicName>rgb/image_raw</imageTopicName>
        <depthImageTopicName>depth/image_raw</depthImageTopicName>
        <pointCloudTopicName>depth/points</pointCloudTopicName>
        <cameraInfoTopicName>rgb/camera_info</cameraInfoTopicName>
        <depthImageCameraInfoTopicName>depth/camera_info</depthImageCameraInfoTopicName>
        <frameName>camera_frame_optical</frameName>
        <baseline>0.1</baseline>
        <distortion_k1>0.0</distortion_k1>
        <distortion_k2>0.0</distortion_k2>
        <distortion_k3>0.0</distortion_k3>
        <distortion_t1>0.0</distortion_t1>
        <distortion_t2>0.0</distortion_t2>
        <pointCloudCutoff>0.4</pointCloudCutoff>
      </plugin>
    </sensor>
  </gazebo>
  <link name="finger_link1">
    <inertial>
      <origin rpy="0 0 0" xyz="0.0187104737539552 0.0170303895104817 -0.000368846804288392"/>
      <mass value="0.0052013516158447"/>
      <inertia ixx="1.83812760924895E-07" ixy="-2.06102890915209E-08" ixz="-2.81175606748554E-10" iyy="1.74961047766009E-06" iyz="7.48427007708597E-11" izz="1.69075281683777E-06"/>
    </inertial>
    <visual>
      <origin rpy="0 0 0" xyz="0 0 0"/>
      <geometry>
        <mesh filename="package://agv_arm/meshes/finger_link1.STL"/>
      </geometry>
      <material name="">
        <color rgba="1 1 1 1"/>
      </material>
    </visual>
    <collision>
      <origin rpy="0 0 0" xyz="0 0 0"/>
      <geometry>
        <mesh filename="package://agv_arm/meshes/finger_link1.STL"/>
      </geometry>
    </collision>
  </link>
  <joint name="finger_joint1" type="prismatic">
    <origin rpy="0 0 0" xyz="0 0 0"/>
    <parent link="link6"/>
    <child link="finger_link1"/>
    <axis xyz="0 -1 0"/>
    <limit effort="1" lower="-0.3" upper="0.3" velocity="1"/>
  </joint>
  <link name="finger_link2">
    <inertial>
      <origin rpy="0 0 0" xyz="0.0187104737539547 -0.0153951860375228 -0.000375520770545479"/>
      <mass value="0.00520135161584462"/>
      <inertia ixx="1.83812760924892E-07" ixy="2.06102890915583E-08" ixz="2.81175606698671E-10" iyy="1.74961047766003E-06" iyz="7.48427007720244E-11" izz="1.6907528168377E-06"/>
    </inertial>
    <visual>
      <origin rpy="0 0 0" xyz="0 0 0"/>
      <geometry>
        <mesh filename="package://agv_arm/meshes/finger_link2.STL"/>
      </geometry>
      <material name="">
        <color rgba="1 1 1 1"/>
      </material>
    </visual>
    <collision>
      <origin rpy="0 0 0" xyz="0 0 0"/>
      <geometry>
        <mesh filename="package://agv_arm/meshes/finger_link2.STL"/>
      </geometry>
    </collision>
  </link>
  <joint name="finger_joint2" type="prismatic">
    <origin rpy="0 0 0" xyz="0 0 0"/>
    <parent link="link6"/>
    <child link="finger_link2"/>
    <axis xyz="0 -1 0"/>
    <limit effort="1" lower="-0.3" upper="0.3" velocity="1"/>
  </joint>
  <link name="front_link1">
    <inertial>
      <origin rpy="0 0 0" xyz="0.00454938714218511 -0.015085259662572 -0.000170656801913083"/>
      <mass value="0.034500655949196"/>
      <inertia ixx="2.12981416033846E-05" ixy="5.75050325361881E-06" ixz="-2.10334644621663E-08" iyy="1.1496091748026E-05" iyz="4.74056732385186E-08" izz="2.38494390827886E-05"/>
    </inertial>
    <visual>
      <origin rpy="0 0 0" xyz="0 0 0"/>
      <geometry>
        <mesh filename="package://agv_arm/meshes/front_link1.STL"/>
      </geometry>
      <material name="">
        <color rgba="1 1 1 1"/>
      </material>
    </visual>
    <collision>
      <origin rpy="0 0 0" xyz="0 0 0"/>
      <geometry>
        <mesh filename="package://agv_arm/meshes/front_link1.STL"/>
      </geometry>
    </collision>
  </link>
  <joint name="front_joint1" type="revolute">
    <origin rpy="1.5708 0 -2.348" xyz="0.4146 -1.7543 -0.34847"/>
    <parent link="base_link"/>
    <child link="front_link1"/>
    <axis xyz="0 -1 0"/>
    <limit effort="1" lower="-1" upper="1" velocity="1"/>
  </joint>
  <link name="front_link2">
    <inertial>
      <origin rpy="0 0 0" xyz="-0.0124999976229834 -9.50171608060657E-11 -6.94045201310445E-08"/>
      <mass value="0.068707123461424"/>
      <inertia ixx="2.95185233018021E-05" ixy="-7.42208136188817E-12" ixz="2.12622845609782E-12" iyy="1.83159672228595E-05" iyz="-1.34415464249044E-12" izz="1.83150441372356E-05"/>
    </inertial>
    <visual>
      <origin rpy="0 0 0" xyz="0 0 0"/>
      <geometry>
        <mesh filename="package://agv_arm/meshes/front_link2.STL"/>
      </geometry>
      <material name="">
        <color rgba="1 1 1 1"/>
      </material>
    </visual>
    <collision>
      <origin rpy="0 0 0" xyz="0 0 0"/>
      <geometry>
        <mesh filename="package://agv_arm/meshes/front_link2.STL"/>
      </geometry>
    </collision>
  </link>
  <joint name="front_joint2" type="revolute">
    <origin rpy="0 1.56255281626515 0" xyz="0.0210289002174014 -0.0600000000000001 -0.0125352292752019"/>
    <parent link="front_link1"/>
    <child link="front_link2"/>
    <axis xyz="1 0 0"/>
    <limit effort="1" lower="-1" upper="1" velocity="1"/>
  </joint>
  <link name="back_link1">
    <inertial>
      <origin rpy="0 0 0" xyz="-0.00346069454949682 -0.0150852596625721 0.00297090233373076"/>
      <mass value="0.0345006559491962"/>
      <inertia ixx="2.25737904320763E-05" ixy="-4.06635819984328E-06" ixz="1.27582213248182E-06" iyy="1.1496091748026E-05" iyz="4.06635782467598E-06" izz="2.25737902540973E-05"/>
    </inertial>
    <visual>
      <origin rpy="0 0 0" xyz="0 0 0"/>
      <geometry>
        <mesh filename="package://agv_arm/meshes/back_link1.STL"/>
      </geometry>
      <material name="">
        <color rgba="1 1 1 1"/>
      </material>
    </visual>
    <collision>
      <origin rpy="0 0 0" xyz="0 0 0"/>
      <geometry>
        <mesh filename="package://agv_arm/meshes/back_link1.STL"/>
      </geometry>
    </collision>
  </link>
  <joint name="back_joint1" type="revolute">
    <origin rpy="1.5707963267949 0 0" xyz="0.726120836980145 -2.01632103140706 -0.348471369887631"/>
    <parent link="base_link"/>
    <child link="back_link1"/>
    <axis xyz="0 -1 0"/>
    <limit effort="1" lower="-1" upper="1" velocity="1"/>
  </joint>
  <link name="back_link2">
    <inertial>
      <origin rpy="0 0 0" xyz="0.0125000023770157 -9.50173828506706E-11 -6.94045209082006E-08"/>
      <mass value="0.0687071234614254"/>
      <inertia ixx="2.9518523301803E-05" ixy="-7.42208142249208E-12" ixz="2.12622844932155E-12" iyy="1.83159672228599E-05" iyz="-1.34415462039289E-12" izz="1.83150441372361E-05"/>
    </inertial>
    <visual>
      <origin rpy="0 0 0" xyz="0 0 0"/>
      <geometry>
        <mesh filename="package://agv_arm/meshes/back_link2.STL"/>
      </geometry>
      <material name="">
        <color rgba="1 1 1 1"/>
      </material>
    </visual>
    <collision>
      <origin rpy="0 0 0" xyz="0 0 0"/>
      <geometry>
        <mesh filename="package://agv_arm/meshes/back_link2.STL"/>
      </geometry>
    </collision>
  </link>
  <joint name="back_joint2" type="revolute">
    <origin rpy="0 -0.785398163397448 0" xyz="-0.0238798361309116 -0.0600000000000001 0.00571237418251203"/>
    <parent link="back_link1"/>
    <child link="back_link2"/>
    <axis xyz="1 0 0"/>
    <limit effort="1" lower="-1" upper="1" velocity="1"/>
  </joint>
  <transmission name="trans_left_joint">
    <type>transmission_interface/SimpleTransmission</type>
    <joint name="left_joint">
      <hardwareInterface>hardware_interface/PositionJointInterface</hardwareInterface>
    </joint>
    <actuator name="left_joint_motor">
      <hardwareInterface>hardware_interface/PositionJointInterface</hardwareInterface>
      <mechanicalReduction>1</mechanicalReduction>
    </actuator>
  </transmission>
  <transmission name="trans_right_joint">
    <type>transmission_interface/SimpleTransmission</type>
    <joint name="right_joint">
      <hardwareInterface>hardware_interface/PositionJointInterface</hardwareInterface>
    </joint>
    <actuator name="right_joint_motor">
      <hardwareInterface>hardware_interface/PositionJointInterface</hardwareInterface>
      <mechanicalReduction>1</mechanicalReduction>
    </actuator>
  </transmission>
  <transmission name="trans_joint1">
    <type>transmission_interface/SimpleTransmission</type>
    <joint name="joint1">
      <hardwareInterface>hardware_interface/PositionJointInterface</hardwareInterface>
    </joint>
    <actuator name="joint1_motor">
      <hardwareInterface>hardware_interface/PositionJointInterface</hardwareInterface>
      <mechanicalReduction>1</mechanicalReduction>
    </actuator>
  </transmission>
  <transmission name="trans_joint2">
    <type>transmission_interface/SimpleTransmission</type>
    <joint name="joint2">
      <hardwareInterface>hardware_interface/PositionJointInterface</hardwareInterface>
    </joint>
    <actuator name="joint2_motor">
      <hardwareInterface>hardware_interface/PositionJointInterface</hardwareInterface>
      <mechanicalReduction>1</mechanicalReduction>
    </actuator>
  </transmission>
  <transmission name="trans_joint3">
    <type>transmission_interface/SimpleTransmission</type>
    <joint name="joint3">
      <hardwareInterface>hardware_interface/PositionJointInterface</hardwareInterface>
    </joint>
    <actuator name="joint3_motor">
      <hardwareInterface>hardware_interface/PositionJointInterface</hardwareInterface>
      <mechanicalReduction>1</mechanicalReduction>
    </actuator>
  </transmission>
  <transmission name="trans_joint4">
    <type>transmission_interface/SimpleTransmission</type>
    <joint name="joint4">
      <hardwareInterface>hardware_interface/PositionJointInterface</hardwareInterface>
    </joint>
    <actuator name="joint4_motor">
      <hardwareInterface>hardware_interface/PositionJointInterface</hardwareInterface>
      <mechanicalReduction>1</mechanicalReduction>
    </actuator>
  </transmission>
  <transmission name="trans_joint5">
    <type>transmission_interface/SimpleTransmission</type>
    <joint name="joint5">
      <hardwareInterface>hardware_interface/PositionJointInterface</hardwareInterface>
    </joint>
    <actuator name="joint5_motor">
      <hardwareInterface>hardware_interface/PositionJointInterface</hardwareInterface>
      <mechanicalReduction>1</mechanicalReduction>
    </actuator>
  </transmission>
  <transmission name="trans_joint6">
    <type>transmission_interface/SimpleTransmission</type>
    <joint name="joint6">
      <hardwareInterface>hardware_interface/PositionJointInterface</hardwareInterface>
    </joint>
    <actuator name="joint6_motor">
      <hardwareInterface>hardware_interface/PositionJointInterface</hardwareInterface>
      <mechanicalReduction>1</mechanicalReduction>
    </actuator>
  </transmission>
  <transmission name="trans_finger_joint1">
    <type>transmission_interface/SimpleTransmission</type>
    <joint name="finger_joint1">
      <hardwareInterface>hardware_interface/PositionJointInterface</hardwareInterface>
    </joint>
    <actuator name="finger_joint1_motor">
      <hardwareInterface>hardware_interface/PositionJointInterface</hardwareInterface>
      <mechanicalReduction>1</mechanicalReduction>
    </actuator>
  </transmission>
  <transmission name="trans_finger_joint2">
    <type>transmission_interface/SimpleTransmission</type>
    <joint name="finger_joint2">
      <hardwareInterface>hardware_interface/PositionJointInterface</hardwareInterface>
    </joint>
    <actuator name="finger_joint2_motor">
      <hardwareInterface>hardware_interface/PositionJointInterface</hardwareInterface>
      <mechanicalReduction>1</mechanicalReduction>
    </actuator>
  </transmission>
  <transmission name="trans_front_joint1">
    <type>transmission_interface/SimpleTransmission</type>
    <joint name="front_joint1">
      <hardwareInterface>hardware_interface/PositionJointInterface</hardwareInterface>
    </joint>
    <actuator name="front_joint1_motor">
      <hardwareInterface>hardware_interface/PositionJointInterface</hardwareInterface>
      <mechanicalReduction>1</mechanicalReduction>
    </actuator>
  </transmission>
  <transmission name="trans_front_joint2">
    <type>transmission_interface/SimpleTransmission</type>
    <joint name="front_joint2">
      <hardwareInterface>hardware_interface/PositionJointInterface</hardwareInterface>
    </joint>
    <actuator name="front_joint2_motor">
      <hardwareInterface>hardware_interface/PositionJointInterface</hardwareInterface>
      <mechanicalReduction>1</mechanicalReduction>
    </actuator>
  </transmission>
  <transmission name="trans_back_joint1">
    <type>transmission_interface/SimpleTransmission</type>
    <joint name="back_joint1">
      <hardwareInterface>hardware_interface/PositionJointInterface</hardwareInterface>
    </joint>
    <actuator name="back_joint1_motor">
      <hardwareInterface>hardware_interface/PositionJointInterface</hardwareInterface>
      <mechanicalReduction>1</mechanicalReduction>
    </actuator>
  </transmission>
  <transmission name="trans_back_joint2">
    <type>transmission_interface/SimpleTransmission</type>
    <joint name="back_joint2">
      <hardwareInterface>hardware_interface/PositionJointInterface</hardwareInterface>
    </joint>
    <actuator name="back_joint2_motor">
      <hardwareInterface>hardware_interface/PositionJointInterface</hardwareInterface>
      <mechanicalReduction>1</mechanicalReduction>
    </actuator>
  </transmission>
  <gazebo>
    <plugin filename="libgazebo_ros_control.so" name="gazebo_ros_control">
      <robotNamespace>/</robotNamespace>
    </plugin>
  </gazebo>
  <!-- /////// Differential drive controller /////////// -->
  <gazebo>
    <plugin filename="libgazebo_ros_diff_drive.so" name="differential_drive_controller">
      <rosDebugLevel>Debug</rosDebugLevel>
      <publishWheelTF>false</publishWheelTF>
      <robotNamespace>/</robotNamespace>
      <publishTf>1</publishTf>
      <publishWheelJointState>false</publishWheelJointState>
      <alwaysOn>true</alwaysOn>
      <updateRate>100.0</updateRate>
      <leftJoint>left_joint</leftJoint>
      <rightJoint>right_joint</rightJoint>
      <wheelSeparation>0.322</wheelSeparation>
      <wheelDiameter>0.195</wheelDiameter>
      <broadcastTF>1</broadcastTF>
      <wheelTorque>30</wheelTorque>
      <wheelAcceleration>1.8</wheelAcceleration>
      <commandTopic>cmd_vel</commandTopic>
      <odometryFrame>odom</odometryFrame>
      <odometryTopic>odom</odometryTopic>
      <robotBaseFrame>base_link</robotBaseFrame>
    </plugin>
  </gazebo>
  <!-- TEST -->
  <!-- camera body, with origin at bottom screw mount -->
  <joint name="d435_joint" type="fixed">
    <origin rpy="0 0 0 " xyz="0 0 0.0"/>
    <parent link="d415_link"/>
    <child link="d435_bottom_screw_frame"/>
  </joint>
  <link name="d435_bottom_screw_frame"/>
  <joint name="d435_link_joint" type="fixed">
    <origin rpy="0 0 0" xyz="0 0.0175 0.0125"/>
    <parent link="d435_bottom_screw_frame"/>
    <child link="d435_link"/>
  </joint>
  <link name="d435_link">
    <visual>
      <origin rpy="1.57079632679 0 1.57079632679" xyz="0.0149 -0.0175 0"/>
      <geometry>
        <mesh filename="package://realsense_ros_gazebo/meshes/realsense_d435.stl"/>
      </geometry>
    </visual>
    <collision>
      <origin rpy="0 0 0" xyz="0 -0.0175 0"/>
      <geometry>
        <box size="0.02505 0.09 0.025"/>
      </geometry>
    </collision>
    <inertial>
      <mass value="0.564"/>
      <origin rpy="0 0 0" xyz="0 -0.0175 0"/>
      <inertia ixx="0.000410075" ixy="0" ixz="0" iyy="5.88676175e-05" iyz="0" izz="5.88676175e-05"/>
    </inertial>
  </link>
  <!-- camera depth joints and links -->
  <joint name="d435_depth_joint" type="fixed">
    <origin rpy="0 0 0" xyz="0 0 0"/>
    <parent link="d435_link"/>
    <child link="d435_depth_frame"/>
  </joint>
  <link name="d435_depth_frame"/>
  <joint name="d435_depth_optical_joint" type="fixed">
    <origin rpy="-1.57079632679 0 -1.57079632679" xyz="0 0 0"/>
    <parent link="d435_depth_frame"/>
    <child link="d435_depth_optical_frame"/>
  </joint>
  <link name="d435_depth_optical_frame"/>
  <!-- camera left IR joints and links -->
  <joint name="d435_left_ir_joint" type="fixed">
    <origin rpy="0 0 0" xyz="0 0.0 0"/>
    <parent link="d435_depth_frame"/>
    <child link="d435_left_ir_frame"/>
  </joint>
  <link name="d435_left_ir_frame"/>
  <joint name="d435_left_ir_optical_joint" type="fixed">
    <origin rpy="-1.57079632679 0 -1.57079632679" xyz="0 0 0"/>
    <parent link="d435_left_ir_frame"/>
    <child link="d435_left_ir_optical_frame"/>
  </joint>
  <link name="d435_left_ir_optical_frame"/>
  <!-- camera right IR joints and links -->
  <joint name="d435_right_ir_joint" type="fixed">
    <origin rpy="0 0 0" xyz="0 -0.05 0"/>
    <parent link="d435_depth_frame"/>
    <child link="d435_right_ir_frame"/>
  </joint>
  <link name="d435_right_ir_frame"/>
  <joint name="d435_right_ir_optical_joint" type="fixed">
    <origin rpy="-1.57079632679 0 -1.57079632679" xyz="0 0 0"/>
    <parent link="d435_right_ir_frame"/>
    <child link="d435_right_ir_optical_frame"/>
  </joint>
  <link name="d435_right_ir_optical_frame"/>
  <!-- camera color joints and links -->
  <joint name="d435_color_joint" type="fixed">
    <origin rpy="0 0 0" xyz="0 0.015 0"/>
    <parent link="d435_depth_frame"/>
    <child link="d435_color_frame"/>
  </joint>
  <link name="d435_color_frame"/>
  <joint name="d435_color_optical_joint" type="fixed">
    <origin rpy="-1.57079632679 0 -1.57079632679" xyz="0 0 0"/>
    <parent link="d435_color_frame"/>
    <child link="d435_color_optical_frame"/>
  </joint>
  <link name="d435_color_optical_frame"/>
  <!-- gazebo plugin -->
  <gazebo reference="d435_link">
    <self_collide>0</self_collide>
    <enable_wind>0</enable_wind>
    <kinematic>0</kinematic>
    <gravity>1</gravity>
    <mu2>1</mu2>
    <fdir1>0 0 0</fdir1>
    <kp>1e+13</kp>
    <kd>1</kd>
    <sensor name="d435_color" type="camera">
      <camera name="d435">
        <horizontal_fov>1.21125850088</horizontal_fov>
        <image>
          <width>640</width>
          <height>480</height>
          <format>RGB_INT8</format>
        </image>
        <clip>
          <near>0.1</near>
          <far>100</far>
        </clip>
        <noise>
          <type>gaussian</type>
          <mean>0.0</mean>
          <stddev>0.007</stddev>
        </noise>
      </camera>
      <always_on>1</always_on>
      <update_rate>30</update_rate>
      <visualize>1</visualize>
    </sensor>
    <sensor name="d435_ired1" type="camera">
      <camera name="d435">
        <horizontal_fov>1.4870205227</horizontal_fov>
        <image>
          <width>1280</width>
          <height>720</height>
          <format>L_INT8</format>
        </image>
        <clip>
          <near>0.1</near>
          <far>100</far>
        </clip>
        <noise>
          <type>gaussian</type>
          <mean>0.0</mean>
          <stddev>0.05</stddev>
        </noise>
      </camera>
      <always_on>1</always_on>
      <update_rate>90</update_rate>
      <visualize>0</visualize>
    </sensor>
    <sensor name="d435_ired2" type="camera">
      <camera name="d435">
        <horizontal_fov>1.4870205227</horizontal_fov>
        <image>
          <width>1280</width>
          <height>720</height>
          <format>L_INT8</format>
        </image>
        <clip>
          <near>0.1</near>
          <far>100</far>
        </clip>
        <noise>
          <type>gaussian</type>
          <mean>0.0</mean>
          <stddev>0.05</stddev>
        </noise>
      </camera>
      <always_on>1</always_on>
      <update_rate>90</update_rate>
      <visualize>0</visualize>
    </sensor>
    <sensor name="d435_depth" type="depth">
      <camera name="d435">
        <horizontal_fov>1.4870205227</horizontal_fov>
        <image>
          <width>1280</width>
          <height>720</height>
        </image>
        <clip>
          <near>0.1</near>
          <far>100</far>
        </clip>
        <noise>
          <type>gaussian</type>
          <mean>0.0</mean>
          <stddev>0.100</stddev>
        </noise>
      </camera>
      <always_on>1</always_on>
      <update_rate>90</update_rate>
      <visualize>0</visualize>
    </sensor>
  </gazebo>
  <gazebo>
    <plugin filename="librealsense_gazebo_plugin.so" name="d435">
      <prefix>d435_</prefix>
      <depthUpdateRate>10</depthUpdateRate>
      <colorUpdateRate>10</colorUpdateRate>
      <infraredUpdateRate>10</infraredUpdateRate>
      <depthTopicName>depth/image_raw</depthTopicName>
      <depthCameraInfoTopicName>depth/camera_info</depthCameraInfoTopicName>
      <colorTopicName>color/image_raw</colorTopicName>
      <colorCameraInfoTopicName>color/camera_info</colorCameraInfoTopicName>
      <infrared1TopicName>infra1/image_raw</infrared1TopicName>
      <infrared1CameraInfoTopicName>infra1/camera_info</infrared1CameraInfoTopicName>
      <infrared2TopicName>infra2/image_raw</infrared2TopicName>
      <infrared2CameraInfoTopicName>infra2/camera_info</infrared2CameraInfoTopicName>
      <colorOpticalframeName>d435_color_optical_frame</colorOpticalframeName>
      <depthOpticalframeName>d435_depth_optical_frame</depthOpticalframeName>
      <infrared1OpticalframeName>d435_infrared1_optical_frame</infrared1OpticalframeName>
      <infrared2OpticalframeName>d435_infrared2_optical_frame</infrared2OpticalframeName>
      <rangeMinDepth>0.2</rangeMinDepth>
      <rangeMaxDepth>10.0</rangeMaxDepth>
      <pointCloud>false</pointCloud>
      <pointCloudTopicName>depth/color/points</pointCloudTopicName>
      <pointCloudCutoff>0.25</pointCloudCutoff>
      <pointCloudCutoffMax>9.0</pointCloudCutoffMax>
    </plugin>
  </gazebo>
</robot>

