<?xml version="1.0" encoding="utf-8"?>
<!-- This URDF was automatically created by SolidWorks to URDF Exporter! Originally created by Stephen Brawner (brawner@gmail.com) 
     Commit Version: 1.6.0-1-g15f4949  Build Version: 1.6.7594.29634
     For more information, please see http://wiki.ros.org/sw_urdf_exporter -->
<robot
  name="agv_arm3">
  <link
    name="base_link">
    <inertial>
      <origin
        xyz="-3.98803348314178E-05 -1.869040170992E-06 0.0698028354228421"
        rpy="0 0 0" />
      <mass
        value="5.35773748413165" />
      <inertia
        ixx="0.0416362082821188"
        ixy="0.00767908584961674"
        ixz="-9.57552739980786E-05"
        iyy="0.100983289572942"
        iyz="-1.3734878631137E-06"
        izz="0.111507828333827" />
    </inertial>
    <visual>
      <origin
        xyz="0 0 0"
        rpy="0 0 0" />
      <geometry>
        <mesh
          filename="package://agv_arm3/meshes/base_link.STL" />
      </geometry>
      <material
        name="">
        <color
          rgba="1 1 1 1" />
      </material>
    </visual>
    <collision>
      <origin
        xyz="0 0 0"
        rpy="0 0 0" />
      <geometry>
        <mesh
          filename="package://agv_arm3/meshes/base_link.STL" />
      </geometry>
    </collision>
  </link>
  <link
    name="left_link">
    <inertial>
      <origin
        xyz="-2.50330754389405E-11 -1.37628312670002E-07 -0.00348654268924592"
        rpy="0 0 0" />
      <mass
        value="1.04300354125074" />
      <inertia
        ixx="0.00314509586133882"
        ixy="9.39676616140868E-12"
        ixz="1.16375265117968E-08"
        iyy="0.00314527309348858"
        iyz="6.92877962504325E-11"
        izz="0.00586686223991632" />
    </inertial>
    <visual>
      <origin
        xyz="0 0 0"
        rpy="0 0 0" />
      <geometry>
        <mesh
          filename="package://agv_arm3/meshes/left_link.STL" />
      </geometry>
      <material
        name="">
        <color
          rgba="1 1 1 1" />
      </material>
    </visual>
    <collision>
      <origin
        xyz="0 0 0"
        rpy="0 0 0" />
      <geometry>
        <mesh
          filename="package://agv_arm3/meshes/left_link.STL" />
      </geometry>
    </collision>
  </link>
  <joint
    name="left_joint"
    type="continuous">
    <origin
      xyz="0 0.1645 0.0325"
      rpy="1.5707963267949 -0.0872664625997164 -3.14159265358979" />
    <parent
      link="base_link" />
    <child
      link="left_link" />
    <axis
      xyz="0 0 -1" />
    <limit
      lower="-1111"
      upper="1111"
      effort="100"
      velocity="10" />
  </joint>
  <link
    name="right_link">
    <inertial>
      <origin
        xyz="-2.50330325045345E-11 -1.37628312586735E-07 -0.00348654268924595"
        rpy="0 0 0" />
      <mass
        value="1.04300354125074" />
      <inertia
        ixx="0.00314509586133882"
        ixy="9.39676624272384E-12"
        ixz="1.16375265118808E-08"
        iyy="0.00314527309348858"
        iyz="6.92877958715914E-11"
        izz="0.00586686223991633" />
    </inertial>
    <visual>
      <origin
        xyz="0 0 0"
        rpy="0 0 0" />
      <geometry>
        <mesh
          filename="package://agv_arm3/meshes/right_link.STL" />
      </geometry>
      <material
        name="">
        <color
          rgba="1 1 1 1" />
      </material>
    </visual>
    <collision>
      <origin
        xyz="0 0 0"
        rpy="0 0 0" />
      <geometry>
        <mesh
          filename="package://agv_arm3/meshes/right_link.STL" />
      </geometry>
    </collision>
  </link>
  <joint
    name="right_joint"
    type="continuous">
    <origin
      xyz="0 -0.1645 0.0325"
      rpy="1.5707963267949 -0.0872664625997165 0" />
    <parent
      link="base_link" />
    <child
      link="right_link" />
    <axis
      xyz="0 0 -1" />
    <limit
      lower="-1111"
      upper="1111"
      effort="100"
      velocity="10" />
  </joint>
  <link
    name="lidar_link">
    <inertial>
      <origin
        xyz="-0.000296153234356333 1.12814554343044E-09 -0.0254717812660583"
        rpy="0 0 0" />
      <mass
        value="0.131588919004453" />
      <inertia
        ixx="7.14622431639145E-05"
        ixy="3.31963504257286E-12"
        ixz="8.65350822889394E-07"
        iyy="7.23109738477126E-05"
        iyz="-2.47141580506267E-12"
        izz="4.46765670225822E-05" />
    </inertial>
    <visual>
      <origin
        xyz="0 0 0"
        rpy="0 0 0" />
      <geometry>
        <mesh
          filename="package://agv_arm3/meshes/lidar_link.STL" />
      </geometry>
      <material
        name="">
        <color
          rgba="1 1 1 1" />
      </material>
    </visual>
    <collision>
      <origin
        xyz="0 0 0"
        rpy="0 0 0" />
      <geometry>
        <mesh
          filename="package://agv_arm3/meshes/lidar_link.STL" />
      </geometry>
    </collision>
  </link>
  <joint
    name="lidar_joint"
    type="fixed">
    <origin
      xyz="0.250826797270742 0 0.225842"
      rpy="0 0 0" />
    <parent
      link="base_link" />
    <child
      link="lidar_link" />
    <axis
      xyz="0 0 0" />
  </joint>
  <link
    name="pwr_link">
    <inertial>
      <origin
        xyz="0.0149998736942567 -0.0149999861468908 -0.0302001764965297"
        rpy="0 0 0" />
      <mass
        value="0.0494933865550185" />
      <inertia
        ixx="2.25636591664424E-05"
        ixy="-1.57492033053765E-11"
        ixz="-1.92996311650402E-10"
        iyy="2.25635485506423E-05"
        iyz="1.88012265258888E-11"
        izz="6.57716485866471E-06" />
    </inertial>
    <visual>
      <origin
        xyz="0 0 0"
        rpy="0 0 0" />
      <geometry>
        <mesh
          filename="package://agv_arm3/meshes/pwr_link.STL" />
      </geometry>
      <material
        name="">
        <color
          rgba="1 1 1 1" />
      </material>
    </visual>
    <collision>
      <origin
        xyz="0 0 0"
        rpy="0 0 0" />
      <geometry>
        <mesh
          filename="package://agv_arm3/meshes/pwr_link.STL" />
      </geometry>
    </collision>
  </link>
  <joint
    name="pwr_joint"
    type="fixed">
    <origin
      xyz="-0.101416866011464 0.148460110886676 0.170842"
      rpy="3.14159265358979 0 3.14159265358979" />
    <parent
      link="base_link" />
    <child
      link="pwr_link" />
    <axis
      xyz="0 0 0" />
  </joint>
  <link
    name="pc_link">
    <inertial>
      <origin
        xyz="0.09 -0.09 -0.055"
        rpy="0 0 0" />
      <mass
        value="3.564" />
      <inertia
        ixx="0.0132165"
        ixy="-1.64022581511141E-18"
        ixz="1.20013749942464E-19"
        iyy="0.0132165"
        iyz="-7.92469639148251E-19"
        izz="0.0192456" />
    </inertial>
    <visual>
      <origin
        xyz="0 0 0"
        rpy="0 0 0" />
      <geometry>
        <mesh
          filename="package://agv_arm3/meshes/pc_link.STL" />
      </geometry>
      <material
        name="">
        <color
          rgba="1 1 1 1" />
      </material>
    </visual>
    <collision>
      <origin
        xyz="0 0 0"
        rpy="0 0 0" />
      <geometry>
        <mesh
          filename="package://agv_arm3/meshes/pc_link.STL" />
      </geometry>
    </collision>
  </link>
  <joint
    name="pc_joint"
    type="fixed">
    <origin
      xyz="0.0894403547066019 0.0899999999999996 0.170842"
      rpy="3.14159265358979 0 3.14159265358979" />
    <parent
      link="base_link" />
    <child
      link="pc_link" />
    <axis
      xyz="0 0 0" />
  </joint>
  <link
    name="arm_base_link">
    <inertial>
      <origin
        xyz="-0.00686650270088979 -6.3890516115404E-05 0.017933458218768"
        rpy="0 0 0" />
      <mass
        value="0.18628772741613" />
      <inertia
        ixx="0.000263033016433508"
        ixy="-1.46506892197407E-06"
        ixz="-2.45566831738087E-06"
        iyy="0.000319273280102255"
        iyz="3.39147302015336E-07"
        izz="0.000520691140482186" />
    </inertial>
    <visual>
      <origin
        xyz="0 0 0"
        rpy="0 0 0" />
      <geometry>
        <mesh
          filename="package://agv_arm3/meshes/arm_base_link.STL" />
      </geometry>
      <material
        name="">
        <color
          rgba="1 1 1 1" />
      </material>
    </visual>
    <collision>
      <origin
        xyz="0 0 0"
        rpy="0 0 0" />
      <geometry>
        <mesh
          filename="package://agv_arm3/meshes/arm_base_link.STL" />
      </geometry>
    </collision>
  </link>
  <joint
    name="arm_base_joint"
    type="fixed">
    <origin
      xyz="0.12 -0.0899999999999999 -0.11"
      rpy="3.14159265358979 0 3.14159265358979" />
    <parent
      link="pc_link" />
    <child
      link="arm_base_link" />
    <axis
      xyz="0 0 0" />
  </joint>
  <link
    name="link1">
    <inertial>
      <origin
        xyz="-0.0567169583181698 -0.00235564072122385 0.000138882700667187"
        rpy="0 0 0" />
      <mass
        value="1.61873888350504" />
      <inertia
        ixx="0.00293110308573468"
        ixy="-3.47507376011122E-05"
        ixz="3.8726154811313E-06"
        iyy="0.00435212480452608"
        iyz="-2.12678311648684E-07"
        izz="0.00438213463950221" />
    </inertial>
    <visual>
      <origin
        xyz="0 0 0"
        rpy="0 0 0" />
      <geometry>
        <mesh
          filename="package://agv_arm3/meshes/link1.STL" />
      </geometry>
      <material
        name="">
        <color
          rgba="0.752941176470588 0.752941176470588 0.752941176470588 1" />
      </material>
    </visual>
    <collision>
      <origin
        xyz="0 0 0"
        rpy="0 0 0" />
      <geometry>
        <mesh
          filename="package://agv_arm3/meshes/link1.STL" />
      </geometry>
    </collision>
  </link>
  <joint
    name="joint1"
    type="revolute">
    <origin
      xyz="0 -0.000105266487493887 0.0548561855519908"
      rpy="1.57079632679491 1.5707963267949 0" />
    <parent
      link="arm_base_link" />
    <child
      link="link1" />
    <axis
      xyz="-1 0 0" />
    <limit
      lower="-11"
      upper="11"
      effort="100"
      velocity="1" />
  </joint>
  <link
    name="link2">
    <inertial>
      <origin
        xyz="-0.0584429220414362 0.187149983529193 -4.31646231643023E-10"
        rpy="0 0 0" />
      <mass
        value="3.79194293522179" />
      <inertia
        ixx="0.120319358955817"
        ixy="4.02878593271949E-07"
        ixz="-3.54541158103531E-11"
        iyy="0.00991240275678066"
        iyz="-2.05377531487273E-05"
        izz="0.12318995186214" />
    </inertial>
    <visual>
      <origin
        xyz="0 0 0"
        rpy="0 0 0" />
      <geometry>
        <mesh
          filename="package://agv_arm3/meshes/link2.STL" />
      </geometry>
      <material
        name="">
        <color
          rgba="0.752941176470588 0.752941176470588 0.752941176470588 1" />
      </material>
    </visual>
    <collision>
      <origin
        xyz="0 0 0"
        rpy="0 0 0" />
      <geometry>
        <mesh
          filename="package://agv_arm3/meshes/link2.STL" />
      </geometry>
    </collision>
  </link>
  <joint
    name="joint2"
    type="revolute">
    <origin
      xyz="-0.0593438144480038 -0.0773990481265728 0.000105266487493693"
      rpy="0.000457884092179863 0 1.57079632679489" />
    <parent
      link="link1" />
    <child
      link="link2" />
    <axis
      xyz="-1 0 0" />
    <limit
      lower="-11"
      upper="11"
      effort="100"
      velocity="1" />
  </joint>
  <link
    name="link3">
    <inertial>
      <origin
        xyz="0.00327709945364583 0.115170432740346 -0.199911913218436"
        rpy="0 0 0" />
      <mass
        value="1.56495747304415" />
      <inertia
        ixx="0.0317713598448578"
        ixy="0.000579721784174367"
        ixz="-0.00100672595897069"
        iyy="0.0250891530022326"
        iyz="0.0127855093188886"
        izz="0.010261180566717" />
    </inertial>
    <visual>
      <origin
        xyz="0 0 0"
        rpy="0 0 0" />
      <geometry>
        <mesh
          filename="package://agv_arm3/meshes/link3.STL" />
      </geometry>
      <material
        name="">
        <color
          rgba="1 1 1 1" />
      </material>
    </visual>
    <collision>
      <origin
        xyz="0 0 0"
        rpy="0 0 0" />
      <geometry>
        <mesh
          filename="package://agv_arm3/meshes/link3.STL" />
      </geometry>
    </collision>
  </link>
  <joint
    name="joint3"
    type="revolute">
    <origin
      xyz="0.0776000000000131 0.374299999999998 0"
      rpy="-2.61707810980682 0 -3.14159265358979" />
    <parent
      link="link2" />
    <child
      link="link3" />
    <axis
      xyz="1 0 0" />
    <limit
      lower="-11"
      upper="11"
      effort="100"
      velocity="1" />
  </joint>
  <link
    name="link4">
    <inertial>
      <origin
        xyz="0.115612552836977 5.68599588126606E-05 -0.000182701670504132"
        rpy="0 0 0" />
      <mass
        value="0.840413041820024" />
      <inertia
        ixx="0.00159983275687532"
        ixy="-1.13064913108001E-06"
        ixz="3.84550144816514E-06"
        iyy="0.00154970394170128"
        iyz="0.000172861052907553"
        izz="0.000948735860596394" />
    </inertial>
    <visual>
      <origin
        xyz="0 0 0"
        rpy="0 0 0" />
      <geometry>
        <mesh
          filename="package://agv_arm3/meshes/link4.STL" />
      </geometry>
      <material
        name="">
        <color
          rgba="1 1 1 1" />
      </material>
    </visual>
    <collision>
      <origin
        xyz="0 0 0"
        rpy="0 0 0" />
      <geometry>
        <mesh
          filename="package://agv_arm3/meshes/link4.STL" />
      </geometry>
    </collision>
  </link>
  <joint
    name="joint4"
    type="revolute">
    <origin
      xyz="-0.00230000000000461 0.171227902195703 -0.297203643163503"
      rpy="-0.524056659690805 0 0" />
    <parent
      link="link3" />
    <child
      link="link4" />
    <axis
      xyz="-1 0 0" />
    <limit
      lower="-11"
      upper="11"
      effort="100"
      velocity="1" />
  </joint>
  <link
    name="link5">
    <inertial>
      <origin
        xyz="0.1156125766376 -7.95706803857765E-06 0.00019112698992832"
        rpy="0 0 0" />
      <mass
        value="0.840414945857114" />
      <inertia
        ixx="0.00159984314472574"
        ixy="1.07453200501053E-07"
        ixz="-4.00464194471819E-06"
        iyy="0.00159587157000826"
        iyz="-2.27692169341203E-07"
        izz="0.000902564205895203" />
    </inertial>
    <visual>
      <origin
        xyz="0 0 0"
        rpy="0 0 0" />
      <geometry>
        <mesh
          filename="package://agv_arm3/meshes/link5.STL" />
      </geometry>
      <material
        name="">
        <color
          rgba="1 1 1 1" />
      </material>
    </visual>
    <collision>
      <origin
        xyz="0 0 0"
        rpy="0 0 0" />
      <geometry>
        <mesh
          filename="package://agv_arm3/meshes/link5.STL" />
      </geometry>
    </collision>
  </link>
  <joint
    name="joint5"
    type="revolute">
    <origin
      xyz="0.117 -0.000594247621559019 0.00222189083181942"
      rpy="1.57079632679491 1.30945482308825 1.5707963267949" />
    <parent
      link="link4" />
    <child
      link="link5" />
    <axis
      xyz="-1 0 0" />
    <limit
      lower="-11"
      upper="11"
      effort="100"
      velocity="1" />
  </joint>
  <link
    name="link6">
    <inertial>
      <origin
        xyz="0.0015000000000005 -6.66133814775094E-16 0.0187669021540481"
        rpy="0 0 0" />
      <mass
        value="0.0100824945905106" />
      <inertia
        ixx="9.87586589022387E-06"
        ixy="3.34053306272289E-23"
        ixz="-2.53554448783418E-22"
        iyy="6.49518733073715E-06"
        iyz="7.30565917006813E-21"
        izz="3.39580230137249E-06" />
    </inertial>
    <visual>
      <origin
        xyz="0 0 0"
        rpy="0 0 0" />
      <geometry>
        <mesh
          filename="package://agv_arm3/meshes/link6.STL" />
      </geometry>
      <material
        name="">
        <color
          rgba="1 1 1 1" />
      </material>
    </visual>
    <collision>
      <origin
        xyz="0 0 0"
        rpy="0 0 0" />
      <geometry>
        <mesh
          filename="package://agv_arm3/meshes/link6.STL" />
      </geometry>
    </collision>
  </link>
  <joint
    name="joint6"
    type="revolute">
    <origin
      xyz="0.117000021796173 0 0.0682000217961732"
      rpy="0.682998608751051 -1.5707963267949 0" />
    <parent
      link="link5" />
    <child
      link="link6" />
    <axis
      xyz="-1 0 0" />
    <limit
      lower="-11"
      upper="11"
      effort="100"
      velocity="1" />
  </joint>
  <link
    name="d415_link">
    <inertial>
      <origin
        xyz="-8.8000818860845E-06 -0.0111114284341225 -0.00437437065673593"
        rpy="0 0 0" />
      <mass
        value="0.0164396902105074" />
      <inertia
        ixx="1.36518255800565E-06"
        ixy="-1.35811642181704E-11"
        ixz="1.86194819294529E-09"
        iyy="1.2970106416684E-05"
        iyz="-4.40746002933799E-08"
        izz="1.31174014911883E-05" />
    </inertial>
    <visual>
      <origin
        xyz="0 0 0"
        rpy="0 0 0" />
      <geometry>
        <mesh
          filename="package://agv_arm3/meshes/d415_link.STL" />
      </geometry>
      <material
        name="">
        <color
          rgba="1 1 1 1" />
      </material>
    </visual>
    <collision>
      <origin
        xyz="0 0 0"
        rpy="0 0 0" />
      <geometry>
        <mesh
          filename="package://agv_arm3/meshes/d415_link.STL" />
      </geometry>
    </collision>
  </link>
  <joint
    name="d415_joint"
    type="fixed">
    <origin
      xyz="0.0140000000000005 0 0.0435000000000011"
      rpy="-1.5707963267949 0 -1.5707963267949" />
    <parent
      link="link6" />
    <child
      link="d415_link" />
    <axis
      xyz="0 0 0" />
  </joint>
  <link
    name="end_Link">
    <inertial>
      <origin
        xyz="-0.0758044009170491 0.00118647369121061 0.000522320190807724"
        rpy="0 0 0" />
      <mass
        value="0.0741731632754536" />
      <inertia
        ixx="4.4731360450387E-05"
        ixy="6.86799798054487E-07"
        ixz="1.20712885235307E-07"
        iyy="9.53974122835655E-05"
        iyz="1.90401790083396E-09"
        izz="0.000106472259830389" />
    </inertial>
    <visual>
      <origin
        xyz="0 0 0"
        rpy="0 0 0" />
      <geometry>
        <mesh
          filename="package://agv_arm3/meshes/end_Link.STL" />
      </geometry>
      <material
        name="">
        <color
          rgba="1 1 1 1" />
      </material>
    </visual>
    <collision>
      <origin
        xyz="0 0 0"
        rpy="0 0 0" />
      <geometry>
        <mesh
          filename="package://agv_arm3/meshes/end_Link.STL" />
      </geometry>
    </collision>
  </link>
  <joint
    name="end_joint"
    type="fixed">
    <origin
      xyz="0.135610184391361 -0.00101183482587985 -0.000569241907415308"
      rpy="0 0 0" />
    <parent
      link="link6" />
    <child
      link="end_Link" />
    <axis
      xyz="0 0 0" />
  </joint>
  <link
    name="finger_link2">
    <inertial>
      <origin
        xyz="0.0187104737539547 -0.0153951860375232 -0.00037552077054534"
        rpy="0 0 0" />
      <mass
        value="0.00520135161584468" />
      <inertia
        ixx="1.83812760924895E-07"
        ixy="2.06102890915611E-08"
        ixz="2.81175606703091E-10"
        iyy="1.74961047766006E-06"
        iyz="7.48427007714497E-11"
        izz="1.69075281683774E-06" />
    </inertial>
    <visual>
      <origin
        xyz="0 0 0"
        rpy="0 0 0" />
      <geometry>
        <mesh
          filename="package://agv_arm3/meshes/finger_link2.STL" />
      </geometry>
      <material
        name="">
        <color
          rgba="1 1 1 1" />
      </material>
    </visual>
    <collision>
      <origin
        xyz="0 0 0"
        rpy="0 0 0" />
      <geometry>
        <mesh
          filename="package://agv_arm3/meshes/finger_link2.STL" />
      </geometry>
    </collision>
  </link>
  <joint
    name="finger_joint2"
    type="prismatic">
    <origin
      xyz="0 0 0"
      rpy="3.14159265358979 0 3.14159265358978" />
    <parent
      link="end_Link" />
    <child
      link="finger_link2" />
    <axis
      xyz="0 -1 0" />
    <limit
      lower="-0.1"
      upper="0.1"
      effort="1"
      velocity="1" />
  </joint>
  <link
    name="finger_link1">
    <inertial>
      <origin
        xyz="0.018710473753955 0.0170303895104813 -0.000368846804288586"
        rpy="0 0 0" />
      <mass
        value="0.00520135161584464" />
      <inertia
        ixx="1.83812760924894E-07"
        ixy="-2.06102890915284E-08"
        ixz="-2.81175606763185E-10"
        iyy="1.74961047766005E-06"
        iyz="7.48427007701638E-11"
        izz="1.69075281683773E-06" />
    </inertial>
    <visual>
      <origin
        xyz="0 0 0"
        rpy="0 0 0" />
      <geometry>
        <mesh
          filename="package://agv_arm3/meshes/finger_link1.STL" />
      </geometry>
      <material
        name="">
        <color
          rgba="1 1 1 1" />
      </material>
    </visual>
    <collision>
      <origin
        xyz="0 0 0"
        rpy="0 0 0" />
      <geometry>
        <mesh
          filename="package://agv_arm3/meshes/finger_link1.STL" />
      </geometry>
    </collision>
  </link>
  <joint
    name="finger_joint1"
    type="prismatic">
    <origin
      xyz="0 0 0"
      rpy="3.14159265358979 0 3.14159265358978" />
    <parent
      link="end_Link" />
    <child
      link="finger_link1" />
    <axis
      xyz="0 -1 0" />
    <limit
      lower="-0.1"
      upper="0.1"
      effort="1"
      velocity="1" />
  </joint>
  <link
    name="front_link1">
    <inertial>
      <origin
        xyz="0.004549387142184 -0.0150852596625734 -0.000170656801888464"
        rpy="0 0 0" />
      <mass
        value="0.0345006559491949" />
      <inertia
        ixx="2.12981416033921E-05"
        ixy="5.75050325361956E-06"
        ixz="-2.10334644735542E-08"
        iyy="1.14960917480254E-05"
        iyz="4.74056732758391E-08"
        izz="2.38494390827954E-05" />
    </inertial>
    <visual>
      <origin
        xyz="0 0 0"
        rpy="0 0 0" />
      <geometry>
        <mesh
          filename="package://agv_arm3/meshes/front_link1.STL" />
      </geometry>
      <material
        name="">
        <color
          rgba="1 1 1 1" />
      </material>
    </visual>
    <collision>
      <origin
        xyz="0 0 0"
        rpy="0 0 0" />
      <geometry>
        <mesh
          filename="package://agv_arm3/meshes/front_link1.STL" />
      </geometry>
    </collision>
  </link>
  <joint
    name="front_joint1"
    type="continuous">
    <origin
      xyz="0.20270815335595 0.0175 0.025"
      rpy="1.5707963267949 0 1.57903983732463" />
    <parent
      link="base_link" />
    <child
      link="front_link1" />
    <axis
      xyz="0 -1 0" />
    <limit
      lower="-1110"
      upper="1110"
      effort="101"
      velocity="11" />
  </joint>
  <link
    name="front_link2">
    <inertial>
      <origin
        xyz="-0.0125 -9.5024E-11 -6.9405E-08"
        rpy="0 0 0" />
      <mass
        value="0.068707" />
      <inertia
        ixx="2.9519E-05"
        ixy="-7.4221E-12"
        ixz="2.1262E-12"
        iyy="1.8316E-05"
        iyz="-1.3442E-12"
        izz="1.8315E-05" />
    </inertial>
    <visual>
      <origin
        xyz="0 0 0"
        rpy="0 0 0" />
      <geometry>
        <mesh
          filename="package://agv_arm3/meshes/front_link2.STL" />
      </geometry>
      <material
        name="">
        <color
          rgba="1 1 1 1" />
      </material>
    </visual>
    <collision>
      <origin
        xyz="0 0 0"
        rpy="0 0 0" />
      <geometry>
        <mesh
          filename="package://agv_arm3/meshes/front_link2.STL" />
      </geometry>
    </collision>
  </link>
  <joint
    name="front_joint2"
    type="continuous">
    <origin
      xyz="0.0210289002174015 -0.06 -0.0125352292752018"
      rpy="0 1.56255281626517 0" />
    <parent
      link="front_link1" />
    <child
      link="front_link2" />
    <axis
      xyz="1 0 0" />
    <limit
      lower="-1910"
      upper="1190"
      effort="111"
      velocity="11" />
  </joint>
  <link
    name="back_link1">
    <inertial>
      <origin
        xyz="0.00034634 0.0045478 -0.015085"
        rpy="0 0 0" />
      <mass
        value="0.034501" />
      <inertia
        ixx="2.385E-05"
        ixy="8.8978E-14"
        ixz="2.6532E-13"
        iyy="2.1298E-05"
        iyz="5.7507E-06"
        izz="1.1496E-05" />
    </inertial>
    <visual>
      <origin
        xyz="0 0 0"
        rpy="0 0 0" />
      <geometry>
        <mesh
          filename="package://agv_arm3/meshes/back_link1.STL" />
      </geometry>
      <material
        name="">
        <color
          rgba="1 1 1 1" />
      </material>
    </visual>
    <collision>
      <origin
        xyz="0 0 0"
        rpy="0 0 0" />
      <geometry>
        <mesh
          filename="package://agv_arm3/meshes/back_link1.STL" />
      </geometry>
    </collision>
  </link>
  <joint
    name="back_joint1"
    type="continuous">
    <origin
      xyz="-0.20285 -0.0175 0.025"
      rpy="0 0 0" />
    <parent
      link="base_link" />
    <child
      link="back_link1" />
    <axis
      xyz="0 0 -1" />
    <limit
      lower="-1110"
      upper="1110"
      effort="110"
      velocity="11" />
  </joint>
  <link
    name="back_link2">
    <inertial>
      <origin
        xyz="6.9405E-08 -9.5024E-11 -0.0125"
        rpy="0 0 0" />
      <mass
        value="0.068707" />
      <inertia
        ixx="1.8315E-05"
        ixy="1.3442E-12"
        ixz="-2.1262E-12"
        iyy="1.8316E-05"
        iyz="-7.4221E-12"
        izz="2.9519E-05" />
    </inertial>
    <visual>
      <origin
        xyz="0 0 0"
        rpy="0 0 0" />
      <geometry>
        <mesh
          filename="package://agv_arm3/meshes/back_link2.STL" />
      </geometry>
      <material
        name="">
        <color
          rgba="1 1 1 1" />
      </material>
    </visual>
    <collision>
      <origin
        xyz="0 0 0"
        rpy="0 0 0" />
      <geometry>
        <mesh
          filename="package://agv_arm3/meshes/back_link2.STL" />
      </geometry>
    </collision>
  </link>
  <joint
    name="back_joint2"
    type="continuous">
    <origin
      xyz="-0.012154 0.020925 -0.06"
      rpy="1.5708 0 -1.5708" />
    <parent
      link="back_link1" />
    <child
      link="back_link2" />
    <axis
      xyz="0 0 1" />
    <limit
      lower="-1110"
      upper="1110"
      effort="110"
      velocity="11" />
  </joint>
</robot>